Workbook

Sheet 組合名簿
A1: No | B1: 氏名 | C1: メールアドレス | D1: ステータス | E1: 契約書送付日 | F1: 契約締結日 | G1: 役職 | H1: 会社 | I1: 入会者区分 | J1: LINE名 | K1: 電話番号 | L1: 住所 | M1: 紹介者 | N1: 備考 | O1: メモ | P1: documentID | Q1: クラウドサインURL | R1: リマインド回数 | S1: (旧契約書) ステータス | T1: (旧契約書) 契約書送付日 | U1: (旧契約書) 契約締結日 | V1: (旧契約書) documentID | W1: (旧契約書) クラウドサインURL | X1: (旧契約書) リマインド回数 | Y1: 訂正メール
A2: 1 | B2: 坂井 博俊 | C2: h.sakai@value-frontier.jp | D2: 契約書送付済 | E2: 46106.805 | G2: 代表取締役会長 | H2: VF | M2: バリューフロンティア | P2: 01mw7dm0xc0vc2kgjs71xjtmxra9z14r | R2: 1 | S2: 契約書送付済 | T2: 46038 | U2: 破棄処理 | Y2: 済み
A3: =IF(B3="","",COUNTA($B$2:B3)) -> 2 | B3: 大塚崇司 | C3: t.otsuka@value-frontier.jp | D3: 契約書送付済 | E3: 46106.805 | G3: 代表取締役社長 | H3: VF | P3: 01mw7dmcxwxj06hz4bexyyt7k6x2q095 | R3: 1 | S3: 組合員契約書締結 | T3: 46038 | U3: 46038 | Y3: 済み
A4: =IF(B4="","",COUNTA($B$2:B4)) -> 3 | B4: 菅原宗紀（すがわらむねのり） | C4: m.sugawara@value-frontier.jp | D4: 組合員契約書締結 | E4: 46106.805 | F4: 46106.843 | G4: 営業 | H4: VF | P4: 01mw7dmyvw7e06yk03t0wb1bdsxpbgrj | Q4: https://www.cloudsign.jp/document/01mw7dmyvw7e06yk03t0wb1bdsxpbgrj/summary | S4: 組合員契約書締結 | T4: 46039 | U4: 46040 | Y4: 済み
A5: =IF(B5="","",COUNTA($B$2:B5)) -> 4 | B5: 小山大貴（こやまだいき） | C5: d.koyama@value-frontier.jp | D5: 組合員契約書締結 | E5: 46106.805 | F5: 46114.697 | G5: 営業 | H5: VF | P5: 01mw7dnftgss41apy7akj1xk54vw8n42 | Q5: https://www.cloudsign.jp/document/01mw7dnftgss41apy7akj1xk54vw8n42/summary | R5: 1 | S5: 組合員契約書締結 | T5: 46039 | U5: 46042 | Y5: 済み
A6: =IF(B6="","",COUNTA($B$2:B6)) -> 5 | B6: 本岡 佳大（もとおかよしひろ） | C6: y.motooka@value-frontier.jp | D6: 契約書送付済 | E6: 46106.808 | G6: 営業 | H6: VF | P6: 01mw7dw7xjhsgsbtpndz8kgqvy79rg52 | R6: 1 | S6: 組合員契約書締結 | T6: 46039 | U6: 46042 | Y6: 済み
A7: =IF(B7="","",COUNTA($B$2:B7)) -> 6 | B7: 中村 友昭（なかむらともあき） | C7: t.nakamura@value-frontier.jp | D7: 組合員契約書締結 | E7: 46106.808 | F7: 46107.335 | G7: 営業 | H7: VF | P7: 01mw7dwedgt1ax422tby764vkvq4mjb1 | Q7: https://www.cloudsign.jp/document/01mw7dwedgt1ax422tby764vkvq4mjb1/summary | S7: 組合員契約書締結 | T7: 46039 | U7: 46040 | Y7: 済み
A8: =IF(B8="","",COUNTA($B$2:B8)) -> 7 | B8: 岡山 愛紗実（おかやまあさみ） | C8: a.okayama@value-frontier.jp | D8: 契約書送付済 | E8: 46106.808 | G8: 営業 | H8: VF | P8: 01mw7dwkxjq33avewrckfest31f4jb51 | R8: 1 | S8: 組合員契約書締結 | T8: 46039 | U8: 46042 | Y8: 済み
A9: =IF(B9="","",COUNTA($B$2:B9)) -> 8 | B9: 堀内 信宏（ほりうちのぶひろ） | C9: n.horiuchi@value-frontier.jp | D9: 組合員契約書締結 | E9: 46106.808 | F9: 46106.816 | G9: 営業 | H9: VF | P9: 01mw7dwsarv5jsd5pvccmcgrfe7yh1sk | Q9: https://www.cloudsign.jp/document/01mw7dwsarv5jsd5pvccmcgrfe7yh1sk/summary | S9: 組合員契約書締結 | T9: 46039 | U9: 46040 | Y9: 済み
A10: =IF(B10="","",COUNTA($B$2:B10)) -> 9 | B10: 久家 梨瑶（クヤ リヨウ） | C10: r.shinohara@value-frontier.jp | D10: 組合員契約書締結 | E10: 46106.808 | F10: 46106.854 | G10: 営業 | H10: VF | P10: 01mw7dx0qqwf99qgfqzdzc9p2vt351w8 | Q10: https://www.cloudsign.jp/document/01mw7dx0qqwf99qgfqzdzc9p2vt351w8/summary | S10: 組合員契約書締結 | T10: 46041 | U10: 46041 | Y10: 済み
A11: =IF(B11="","",COUNTA($B$2:B11)) -> 10 | B11: 野村 巡（ノムラ ジュン） | C11: j.nomura@value-frontier.jp | D11: 契約書送付済 | E11: 46106.808 | G11: 営業 | H11: VF | P11: 01mw7dx77efqj1vzdkbk7v2x8j78r4fr | R11: 1 | S11: 組合員契約書締結 | T11: 46041 | U11: 46041 | Y11: 済み
A12: =IF(B12="","",COUNTA($B$2:B12)) -> 11 | B12: 日髙 圭（ヒダカ ケイ） | C12: k.hidaka@value-frontier.jp | D12: 組合員契約書締結 | E12: 46106.808 | F12: 46114.73 | G12: 営業 | H12: VF | P12: 01mw7dxcrbd9cgwyd1gkc3wtx2g6qfks | Q12: https://www.cloudsign.jp/document/01mw7dxcrbd9cgwyd1gkc3wtx2g6qfks/summary | R12: 1 | S12: 組合員契約書締結 | T12: 46041 | U12: 46042 | Y12: 済み
A13: =IF(B13="","",COUNTA($B$2:B13)) -> 12 | B13: 田中創作 | C13: sousaku0113@gmail.com | D13: 契約書送付済 | E13: 46106.808 | G13: 理事 | H13: Nuクリニック | P13: 01mw7dxhbzxt424n588n0sr92weqfrr9 | R13: 1 | S13: 組合員契約書締結 | T13: 46039 | U13: 46040 | Y13: 済み
A14: =IF(B14="","",COUNTA($B$2:B14)) -> 13 | B14: 新沼直哉 | C14: niinumanaoya@sedent.co.jp | D14: 組合員契約書締結 | E14: 46106.808 | F14: 46114.769 | G14: 代表取締役社長 | H14: 株式会社セキムラ | P14: 01mw7dxqadpx492s6e3d9zy5kmcmhqxd | Q14: https://www.cloudsign.jp/document/01mw7dxqadpx492s6e3d9zy5kmcmhqxd/summary | R14: 1 | S14: 組合員契約書締結 | T14: 46039 | U14: 46040 | Y14: 済み
A15: =IF(B15="","",COUNTA($B$2:B15)) -> 14 | B15: 木村久美子 | C15: kimura@sedent.co.jp | D15: 不要データ | H15: 新沼さんと同じ会社 | S15: 契約破棄 | T15: 46039
A16: =IF(B16="","",COUNTA($B$2:B16)) -> 15 | B16: 川添恭伯 | C16: y.kawazoe@coaris.co.jp | D16: 組合員契約書締結 | E16: 46106.808 | F16: 46108.419 | G16: 代表取締役社長 | P16: 01mw7dxx2vb5bvsbfej54vcemahdhv71 | Q16: https://www.cloudsign.jp/document/01mw7dxx2vb5bvsbfej54vcemahdhv71/summary | S16: 組合員契約書締結 | T16: 46040 | U16: 46040 | Y16: 済み
A17: =IF(B17="","",COUNTA($B$2:B17)) -> 16 | B17: 渡邉勝紀 | C17: k.watanabe@kotonohamarketing.com | D17: 組合員契約書締結 | E17: 46106.808 | F17: 46107.406 | H17: スタイルエッジ | P17: 01mw7dy3ga388jq27yp89vbe45n4g40a | Q17: https://www.cloudsign.jp/document/01mw7dy3ga388jq27yp89vbe45n4g40a/summary | S17: 組合員契約書締結 | T17: 46041 | U17: 46044 | Y17: 済み
A18: =IF(B18="","",COUNTA($B$2:B18)) -> 17 | B18: 鈴木孝一郎 | C18: swimno1.516@gmail.com | D18: 契約書送付済 | E18: 46106.808 | G18: 弊社 | H18: Stella | P18: 01mw7dy81kcjq8dted7pfkpqz4reybh9 | R18: 1 | S18: 組合員契約書締結 | T18: 46042 | U18: 46042 | Y18: 済み
A19: =IF(B19="","",COUNTA($B$2:B19)) -> 18 | B19: 高畑智弘 | C19: takahata@ensolu.jp | D19: 契約書送付済 | E19: 46106.808 | G19: 代表取締役/セールスコンサルタント ブランディング戦略プロデューサー | H19: 株式会社エンジン&ソリューションズ | P19: 01mw7dyfz5cfnqdt2maxm8g6abbx2tsq | R19: 1 | S19: 組合員契約書締結 | T19: 46042 | U19: 46042 | Y19: 済み
A20: =IF(B20="","",COUNTA($B$2:B20)) -> 19 | B20: 井久保 大介 | C20: d.ikubo@pricom.jp | D20: 契約書送付済 | E20: 46106.808 | G20: 代表者 | H20: 株式会社プリコム | M20: バリューフロンティア | O20: 2/18再送 | P20: 01mw7dyvtst5f529skmmq8zcaggaye7w | R20: 1 | S20: 組合員契約書締結 | T20: 46042 | U20: 46071 | Y20: 済み
A21: =IF(B21="","",COUNTA($B$2:B21)) -> 20 | B21: 大津山裕介 | C21: yusuke-otsuyama@new-create.jp | D21: 契約書送付済 | E21: 46106.812 | G21: 代表者 | H21: 株式会社NEWCREATE | M21: バリューフロンティア | P21: 01mw7eapx2ff3ta6hx8ft29qnsve4r06 | R21: 1 | S21: 契約破棄 | T21: 46042 | U21: 破棄処理 | V21: 01mpy6wnt70mvc4v6f3zjtvrcd50rxv2 | X21: 4 | Y21: 済み
A22: =IF(B22="","",COUNTA($B$2:B22)) -> 21 | B22: 草野純広 | C22: utopia5571@gmail.com | D22: 契約書送付済 | E22: 46106.808 | G22: 代表者 | H22: 株式会社ＴＲＩＰ | M22: バリューフロンティア | O22: 2/18再送 | P22: 01mw7dz479h608n4h6t8xh10j55s8drq | R22: 1 | S22: 組合員契約書締結 | T22: 46042 | U22: 46071 | Y22: 済み
A23: =IF(B23="","",COUNTA($B$2:B23)) -> 22 | B23: 花田誉宜 | C23: aspo@office.email.ne.jp | D23: 組合員契約書締結 | E23: 46106.808 | F23: 46112.424 | G23: 代表者 | H23: aspo株式会社 | M23: バリューフロンティア | P23: 01mw7dz9segxe9415y4npz9rjpjm9ad4 | Q23: https://www.cloudsign.jp/document/01mw7dz9segxe9415y4npz9rjpjm9ad4/summary | S23: 組合員契約書締結 | T23: 46042 | U23: 46042 | Y23: 済み
A24: =IF(B24="","",COUNTA($B$2:B24)) -> 23 | B24: 菊池 幸宏 | C24: miyatozipapa@me.com | D24: 契約書送付済 | E24: 46106.808 | P24: 01mw7dzfm6vy1aycd25actcj76797740 | R24: 1 | S24: 組合員契約書締結 | T24: 46043 | U24: 46045 | Y24: 済み
A25: =IF(B25="","",COUNTA($B$2:B25)) -> 24 | B25: 石田敏之 | C25: ishida1410@gmail.com | D25: 契約書送付済 | E25: 46106.808 | P25: 01mw7dznmvn5q92k5t1yxf20qs7w86wz | R25: 1 | S25: 組合員契約書締結 | T25: 46043 | U25: 46044 | Y25: 済み
A26: =IF(B26="","",COUNTA($B$2:B26)) -> 25 | B26: 吉川 泰一 | C26: y.yoshikawa@aragan-group.com | D26: 契約書送付済 | E26: 46106.809 | P26: 01mw7dzvsk7853ram1gx9x61ngy8zcrd | R26: 1 | S26: 組合員契約書締結 | T26: 46043 | U26: 46050 | Y26: 済み
A27: =IF(B27="","",COUNTA($B$2:B27)) -> 26 | B27: 有馬恵樹 | C27: mcstbm@gmail.com | D27: 組合員契約書締結 | E27: 46106.809 | F27: 46106.83 | P27: 01mw7e038cfwwcpjn9z7pqqg50rzxtfa | Q27: https://www.cloudsign.jp/document/01mw7e038cfwwcpjn9z7pqqg50rzxtfa/summary | S27: 組合員契約書締結 | T27: 46043 | U27: 46045 | Y27: 済み
A28: =IF(B28="","",COUNTA($B$2:B28)) -> 27 | B28: 森光朝陽 | C28: llihc.ital51@gmail.com | D28: 契約書送付済 | E28: 46106.809 | G28: AS | P28: 01mw7e08qnj7kw2m5j91d2xxhccrc6k3 | R28: 1 | S28: 組合員契約書締結 | T28: 46042 | U28: 46043 | Y28: 済み
A29: =IF(B29="","",COUNTA($B$2:B29)) -> 28 | B29: 川満惇平 | C29: jkkjjunpei@gmail.com | D29: 契約書送付済 | E29: 46106.809 | G29: AS | P29: 01mw7e0e52h8ttps2v2e4qgfzmed6eba | R29: 1 | S29: 組合員契約書締結 | T29: 46042 | U29: 46043 | Y29: 済み
A30: =IF(B30="","",COUNTA($B$2:B30)) -> 29 | B30: 天野来海 | C30: amnkrm01@gmail.com | D30: 組合員契約書締結 | E30: 46106.809 | F30: 46111.608 | G30: AS | P30: 01mw7e0mtfynr5gh512nen1jgfpwe6w7 | Q30: https://www.cloudsign.jp/document/01mw7e0mtfynr5gh512nen1jgfpwe6w7/summary | S30: 組合員契約書締結 | T30: 46042 | U30: 46043 | Y30: 済み
A31: =IF(B31="","",COUNTA($B$2:B31)) -> 30 | B31: 尾崎由紀 | C31: xocuvw5735@yahoo.co.jp | D31: 組合員契約書締結 | E31: 46106.809 | F31: 46106.812 | G31: 理事 | P31: 01mw7e0w0jw9nrvd98a69tk5t12j0t7n | Q31: https://www.cloudsign.jp/document/01mw7e0w0jw9nrvd98a69tk5t12j0t7n/summary | S31: 組合員契約書締結 | T31: 46041 | U31: 46042 | Y31: 済み
A32: =IF(B32="","",COUNTA($B$2:B32)) -> 31 | B32: 芝田陽祐 | C32: clover.lcozz@gmail.com | D32: 契約書送付済 | E32: 46106.809 | O32: 再送※2026/1/25 | P32: 01mw7e12ytfc3v1p75cstbg3f8wk3z0w | R32: 1 | S32: 組合員契約書締結 | T32: 46044 | U32: 46049 | Y32: 済み
A33: =IF(B33="","",COUNTA($B$2:B33)) -> 32 | B33: 村主健太 | C33: kenta1721@gmail.com | D33: 契約書送付済 | E33: 46106.809 | O33: 再送※2026/1/26 | P33: 01mw7e182dckv8gdr0tz6178k2dbzfzv | R33: 1 | S33: 組合員契約書締結 | T33: 46044 | U33: 46048 | Y33: 済み
A34: 33 | B34: 木原卓男 | C34: kihara@mirai-support-center.org | D34: 契約書未送付 | E34: 46106.812 | P34: 01mw7eaw2cnmvye3r0n5t7sa06jt09ht | R34: 1 | S34: 契約破棄 | T34: 46044 | U34: 破棄処理 | V34: 01mq3grmv4gpmh1xck0244jnfb4qmx4c | X34: 4 | Y34: 済み
A35: =IF(B35="","",COUNTA($B$2:B35)) -> 34 | B35: 田岡春幸 | C35: taoka0415@gmail.com | D35: 契約書送付済 | E35: 46106.813 | G35: 顧問・代表者 | H35: ヒューマンリスクマネジメント株式会社 | P35: 01mw7eb11jz5h7cjavrbv1vbjpasggtt | R35: 1 | S35: 組合員契約書締結 | T35: 46044 | U35: 46044 | Y35: 済み
A36: =IF(B36="","",COUNTA($B$2:B36)) -> 35 | B36: 斎藤充 | C36: saito@gs-payment.co.jp | D36: 契約書送付済 | E36: 46106.809 | P36: 01mw7e1jn3ervjsnkxe7s91hsgn5xf01 | R36: 1 | S36: 組合員契約書締結 | T36: 46047 | U36: 46055 | Y36: 済み
A37: =IF(B37="","",COUNTA($B$2:B37)) -> 36 | B37: 島倉優奈 | C37: tinyisland117@gmail.com | D37: 組合員契約書締結 | E37: 46106.81 | F37: 46113.437 | H37: Stella | P37: 01mw7e1r4c65ms2ymzsc05q1tmn2yyge | Q37: https://www.cloudsign.jp/document/01mw7e1r4c65ms2ymzsc05q1tmn2yyge/summary | S37: 組合員契約書締結 | T37: 46048 | U37: 46048 | Y37: 済み
A38: =IF(B38="","",COUNTA($B$2:B38)) -> 37 | B38: 塩澤和真 | C38: kazuma.shiozawa0816@gmail.com | D38: 組合員契約書締結 | E38: 46106.81 | F38: 46106.973 | P38: 01mw7e1ypwca6bazf1k3843gjax329q9 | Q38: https://www.cloudsign.jp/document/01mw7e1ypwca6bazf1k3843gjax329q9/summary | S38: 組合員契約書締結 | T38: 46048 | U38: 46049 | Y38: 済み
A39: =IF(B39="","",COUNTA($B$2:B39)) -> 38 | B39: 町田太朗 | C39: taro.machida@airx.co.jp | D39: 契約書送付済 | E39: 46106.81 | G39: コーポレート部門Director | H39: 株式会社AirX | P39: 01mw7e23d5nkz8gy5992prdsnjjkhf19 | R39: 1 | S39: 契約破棄 | T39: 46049 | U39: 破棄処理 | V39: 01mqgvakjnrpynqzdvagwjp6d0d5pexj | X39: 4 | Y39: 済み
A40: =IF(B40="","",COUNTA($B$2:B40)) -> 39 | B40: 福栄祐吾 | C40: yugo@airx.co.jp | D40: 契約書送付済 | E40: 46106.81 | G40: コーポレート部門人事部長 | H40: 株式会社AirX | P40: 01mw7e29y5h2kf44en62c7c97j9hk2ex | R40: 1 | S40: 契約破棄 | T40: 46049 | U40: 破棄処理 | V40: 01mqgvhcsc2b4swe1x84knqkk4wtc69s | X40: 4 | Y40: 済み
...

Sheet 面談実施リスト
A1: № | B1: 氏名 | C1: 企業名 | D1: 日付 | E1: 担当者 | F1: 紹介者 | G1: 代理店％ | H1: ステータス
B2: 木原 | D2: 46035 | E2: 尾崎 | G2: 1％ | H2: 面談実施
B3: 高畑 | D3: 46042 | E3: 尾崎 | G3: 1％ | H3: 面談実施
B4: 手塚 | C4: 株式会社AirX | D4: 46049 | E4: 尾崎 | F4: 創作さん | H4: お見送り
B5: 新沼 | C5: 株式会社セキムラ | D5: 46049 | E5: 尾崎 | F5: 創作さん | H5: 概算お渡し済み
B6: 川添 | C6: COARIS | D6: 46051 | E6: 尾崎 | G6: 1％ | H6: 面談実施
B7: 渡邊 | C7: kotonoha | D7: 46051 | E7: 尾崎 | G7: 1％ | H7: 面談実施
B8: 今川 | D8: 46052 | E8: 尾崎 | G8: 1％ | H8: 面談実施
B9: 花蜜 | D9: 46052 | E9: 尾崎 | G9: 1％ | H9: 面談実施

Sheet シート11
B2: 平均給与 | C2: 300000 | G2: 目標 | H2: 300000000
B3: 人数 | C3: 100 | G3: 1人当たり | H3: 150000
B4: １人あたりの導入金額 | C4: 100000
B6: 初期費用 | C6: =C3*C4 -> 10000000
B7: 既存の社会保険料/月 | C7: 30000
B8: 削減金額/月 | C8: 18000
B9: 削減額合計 | C9: =C8*C3 -> 1800000
B11: 月額利用料/人 | C11: 1000
B12: 月額利用料総額 | C12: =C11*C3 -> 100000
B16: 回収まで | C16: =C6/C9 -> 5.5555556 | D16: ヶ月

Sheet 契約書一覧
A1: 契約書名 | B1: ドライブURL | C1: ステータス
A2: 組合員契約書 | B2: ★一般社団法人_公的制度教育推進協会組合員契約書_修正_0321YS.docx - Google ドキュメント | C2: リーガルチェック済
A3: 組合規定書 | B3: ★一般社団法人_公的制度教育推進協会組合規定書_修正_0321YS.docx - Google ドキュメント | C3: リーガルチェック済
A4: 受託開発契約書 開発企業×企業 | B4: ★受託開発契約書＿開発会社×企業_0324YS.docx - Google ドキュメント | C4: 修正中
A5: 給与評価制度適正化支援契約書 一般社団法人×企業 | B5: ★給与評価制度適正化支援契約書＿一般社団法人×企業_0324YS.docx - Google ドキュメント | C5: リーガルチェック済
A6: 代理店契約書 開発会社×代理店 | B6: ★代理店契約書＿開発会社×代理店_0324YS.docx - Google ドキュメント | C6: 修正中
A7: 組合契約書 法人用 | B7: ★一般社団法人_公的制度教育推進協会組合契約書_修正_法人用 - Google ドキュメント | C7: リーガルチェック済
A8: 組合規定書 法人用 | B8: ★一般社団法人_公的制度教育推進協会組合規定書_修正_法人用.docx - Google ドキュメント | C8: リーガルチェック済 | I8: 企業研修
A9: システム販売契約書 | B9: システム販売・導入契約書 - Google ドキュメント | C9: 作成中
A10: システム仕様書 | B10: 職能評価システム 仕様書（テンプレ） - Google ドキュメント | C10: 作成中
A11: 今後の代理店契約書

Sheet 自動化
A2: 回答用_メインフォーム | B2: https://forms.gle/zftF5VZPxHCRYtrCA
A3: 編集用_メインフォーム | B3: https://docs.google.com/forms/d/1aGe_IjCSVTHPEwQ5okrSzLf0ddRNFOKZG8qZ0zNkUGU/edit
A4: VF専用_回答用_メインフォーム | B4: https://forms.gle/yHVUY6hzuTyuUWde6
A5: VF専用_編集用_メインフォーム | B5: https://docs.google.com/forms/d/1brpnY6VBoPnuO735oC0RhDV8gI_uTWB0_HCI6Q_lQKY/edit
A6: VF中間シート | B6: https://docs.google.com/spreadsheets/d/1C6NymtxuBqP1vLMswJTxDnX0SxvtIdsO8BoHSH5eOrs/edit?usp=sharing
A7: VF側シート | B7: https://docs.google.com/spreadsheets/d/1qjNACHsS6r82qBPFERNrDExtIhi9m3iv/edit?gid=380300159#gid=380300159

Sheet 案件管理シート
A2: 案件番号 | B2: 案件起票日 | C2: 年金事務所への電話 | D2: AS担当者 | E2: 顧客区分 | F2: 都道府県 | G2: 管轄の年金事務所 | H2: 年金事務所担当者名 | I2: 企業名 | J2: 算定基礎届・源泉徴収簿 | K2: 代表者名 | L2: 紹介者 | M2: 業種 | N2: ステータス | O2: 概算見積リンク | P2: 希望者名簿 | Q2: 最大申請人数 | R2: 想定申請人数 | S2: 想定最大還付額 | T2: 想定還付金額 | U2: 確定還付金額 | V2: 弊社想定売上(※開発費) | W2: 確定想定売上(※開発費) | X2: 想定代理店報酬 | Y2: 確定代理店売上 | Z2: 次のアクション | AA2: 次に連絡する日 | AB2: 初回商談日 | AC2: 想定申請日 | AD2: 確定申請日 | AE2: 想定充当通知日 | AF2: 確定充当通知日 | AG2: 想定還付日 | AH2: 確定還付日 | AI2: 想定伊藤先生報酬額 | AJ2: 想定伊藤先生支払日 | AK2: 確定伊藤先生報酬額 | AL2: 確定伊藤先生支払日 | AM2: 想定弊社報酬額 | AN2: 想定弊社支払日 | AO2: 確定弊社報酬額 | AP2: 確定弊社支払日
A3: 0 | D3: 尾崎 | F3: 東京 | G3: 港年金事務所 | H3: 岩下さん | I3: Stella株式会社
A4: 1 | B4: 46069 | D4: 鈴木 | E4: クライアント | F4: 大阪 | G4: 八尾年金事務所 | I4: 株式会社 アポロホールディングス | J4: https://drive.google.com/drive/folders/1KPrf6Fev_4qbIKuUJrqsfUrmJd_7cC26?usp=sharing | M4: 美容業 | N4: 概算提案フェーズ | Q4: 107 | R4: =Q4*80% -> 85.6 | T4: =S4*0.5 -> 0 | V4: =T4*0.2*0.8 -> 0 | X4: =T4*0.1 -> 0 | AC4: =AB4+30 -> 30 | AE4: =AC4+60 -> 90 | AG4: =AE4+60 -> 150 | AI4: =T4*5% -> 0 | AJ4: =AG4+45 -> 195 | AM4: =T4*10% -> 0 | AN4: =AG4+30 -> 180
A5: 2 | B5: 46069 | D5: 鈴木 | E5: クライアント | F5: 東京 | G5: 大手前年金事務所 | I5: 株式会社 アポロプランニング | J5: https://drive.google.com/drive/folders/1KPrf6Fev_4qbIKuUJrqsfUrmJd_7cC26?usp=sharing | M5: 観光業 | N5: 概算提案フェーズ | Q5: 354 | R5: =Q5*80% -> 283.2 | T5: =S5*0.5 -> 0 | V5: =T5*0.2*0.8 -> 0 | X5: =T5*0.1 -> 0 | AC5: =AB5+30 -> 30 | AE5: =AC5+60 -> 90 | AG5: =AE5+60 -> 150 | AI5: =T5*5% -> 0 | AJ5: =AG5+45 -> 195 | AM5: =T5*10% -> 0 | AN5: =AG5+30 -> 180
A6: 3 | B6: 46069 | C6: 待ち | D6: 尾崎 | E6: クライアント | F6: 神奈川 | G6: 小田原年金事務所 | I6: 株式会社 琴美建設 | J6: https://drive.google.com/drive/folders/1OyTAtQzaBoJZMhqieuT8p-uww35EvR_s?usp=sharing | K6: 今川将文 | L6: 望月さん | M6: 建設業 | N6: 概算提案フェーズ | O6: 株式会社美琴建設 | Q6: 17 | R6: =Q6*80% -> 13.6 | S6: 15573557 | T6: =S6*0.5 -> 7786778.5 | V6: =T6*0.2*0.8 -> 1245884.6 | X6: =T6*0.1 -> 778677.85 | AC6: =AB6+30 -> 30 | AE6: =AC6+60 -> 90 | AG6: =AE6+60 -> 150 | AI6: =T6*5% -> 389338.92 | AJ6: =AG6+45 -> 195 | AM6: =T6*10% -> 778677.85 | AN6: =AG6+30 -> 180
A7: 4 | B7: 46069 | D7: 飯塚 | E7: クライアント | F7: 東京 | G7: 足立年金事務所 | I7: 株式会社RISE様 | J7: https://drive.google.com/drive/folders/1dwakvflY9pOgv_Mp840by1MsEE3Bql6Q?usp=sharing | K7: 小室立 | L7: 直 | M7: 美容業 | N7: 概算提案フェーズ | O7: output_株式会社RISE | Q7: 23 | R7: =Q7*80% -> 18.4 | S7: 28530256 | T7: =S7*0.5 -> 14265128 | V7: =T7*0.2*0.8 -> 2282420.5 | X7: =T7*0.1 -> 1426512.8 | AC7: =AB7+30 -> 30 | AE7: =AC7+60 -> 90 | AG7: =AE7+60 -> 150 | AI7: =T7*5% -> 713256.4 | AJ7: =AG7+45 -> 195 | AM7: =T7*10% -> 1426512.8 | AN7: =AG7+30 -> 180
A8: 5 | B8: 46069 | D8: 鈴木 | E8: クライアント | F8: 東京 | G8: 新宿年金事務所 | I8: 株式会社ＭａｉｎＣ様 | J8: https://drive.google.com/drive/folders/1V3kxanVQkv1LMgU2Y1ynsv8QwceoN9ud?usp=sharing | K8: 辻亮 | L8: 直 | M8: 飲食業 | N8: 概算提案フェーズ | O8: output_株式会社MainC | Q8: 15 | R8: =Q8*80% -> 12 | S8: 10826393 | T8: =S8*0.5 -> 5413196.5 | V8: =T8*0.2*0.8 -> 866111.44 | X8: =T8*0.1 -> 541319.65 | AC8: =AB8+30 -> 30 | AE8: =AC8+60 -> 90 | AG8: =AE8+60 -> 150 | AI8: =T8*5% -> 270659.83 | AJ8: =AG8+45 -> 195 | AM8: =T8*10% -> 541319.65 | AN8: =AG8+30 -> 180
A9: 6 | B9: 46069 | C9: 済み | D9: 尾崎 | E9: クライアント | F9: 大阪 | G9: 淀川年金事務所 | I9: 株式会社バリューフロンティア | J9: https://drive.google.com/drive/folders/1RXvJ0YVUGTVlXtPxy0UZ7raPoaBBH7e9?usp=sharing | K9: 大塚崇司 | L9: 望月さん | M9: 営業 | N9: 申請フェーズ | Q9: 52 | R9: =Q9*80% -> 41.6 | T9: =S9*0.5 -> 0 | V9: =T9*0.2*0.8 -> 0 | X9: =T9*0.1 -> 0 | AC9: =AB9+30 -> 30 | AE9: =AC9+60 -> 90 | AG9: =AE9+60 -> 150 | AI9: =T9*5% -> 0 | AJ9: =AG9+45 -> 195 | AM9: =T9*10% -> 0 | AN9: =AG9+30 -> 180
A10: 7 | B10: 46069 | C10: 待ち | D10: 尾崎 | E10: クライアント | F10: 東京 | G10: 佐原年金事務所 | I10: 株式会社Good Work Japan | J10: https://drive.google.com/drive/folders/15YhdKX2gbnH2pfEgAsIysrjnsHQGT6zz?usp=sharing | K10: 吉田さん | L10: 創作 | M10: 人材業 | N10: 概算提案フェーズ | O10: ファイルサイズが大きい為別途送付可能 | Q10: 1945 | R10: =Q10*80% -> 1556 | S10: 672409696 | T10: =S10*0.5 -> 336204848 | AC10: =AB10+30 -> 30 | AE10: =AC10+60 -> 90 | AG10: =AE10+60 -> 150 | AI10: =T10*5% -> 16810242 | AJ10: =AG10+45 -> 195 | AM10: =T10*10% -> 33620485 | AN10: =AG10+30 -> 180
A11: 8 | B11: 46083 | D11: 尾崎 | E11: クライアント | F11: 東京 | G11: 渋谷年金事務所 | I11: リアンクリニック（一般社団法人LIEN） | J11: https://drive.google.com/drive/folders/1s-xQ5KPC2BhuPd28epESClY0K-KYu2yQ?usp=sharing | K11: 藤尾謙太 | L11: 創作 | M11: 美容クリニック | N11: 申請フェーズ | O11: output_一般社団法人LIEN | Q11: 29 | R11: =Q11*80% -> 23.2 | S11: 60346992 | T11: =S11*0.5 -> 30173496 | AC11: =AB11+30 -> 30 | AE11: =AC11+60 -> 90 | AG11: =AE11+60 -> 150 | AI11: =T11*5% -> 1508674.8 | AJ11: =AG11+45 -> 195 | AM11: =T11*10% -> 3017349.6 | AN11: =AG11+30 -> 180
A12: 9 | B12: 46083 | D12: 尾崎 | E12: クライアント/代理店 | F12: 愛知 | G12: 鶴舞年金事務所 | I12: ジェイシップセントラル | J12: https://drive.google.com/drive/folders/1Ry1wQBQ7QC52-TJOOZvp6S-q6rshBXtH?usp=sharing | K12: 三好恭統 | L12: 創作 | M12: 人材採用 | N12: 申請フェーズ | O12: ジェイシップセントラル㈱ | Q12: 27 | R12: =Q12*80% -> 21.6 | S12: 31621501 | T12: =S12*0.5 -> 15810750 | AC12: =AB12+30 -> 30 | AE12: =AC12+60 -> 90 | AG12: =AE12+60 -> 150 | AI12: =T12*5% -> 790537.53 | AJ12: =AG12+45 -> 195 | AM12: =T12*10% -> 1581075.1 | AN12: =AG12+30 -> 180
A13: 10 | B13: 46083 | C13: 待ち | D13: 尾崎 | E13: クライアント | F13: 東京 | G13: 宮崎年金事務所 | I13: aspo株式会社 | J13: https://drive.google.com/drive/folders/1zDPa_Z9wF6SkvOoi0WWV0R0nvTCzNhZG?usp=sharing | K13: 花田 誉宜 | L13: VF | M13: 健康経営支援 | N13: 概算提案フェーズ | O13: output_株式会社aspo.xlsx | Q13: 74 | R13: =Q13*80% -> 59.2 | S13: 38219349 | T13: =S13*0.5 -> 19109674 | AC13: =AB13+30 -> 30 | AE13: =AC13+60 -> 90 | AG13: =AE13+60 -> 150 | AI13: =T13*5% -> 955483.72 | AJ13: =AG13+45 -> 195 | AM13: =T13*10% -> 1910967.4 | AN13: =AG13+30 -> 180
A14: 11 | B14: 46083 | C14: 待ち | D14: 尾崎 | E14: クライアント | F14: 東京 | G14: 港年金事務所 | I14: 株式会社NEXT（旧: 株式会社ADOLOGI） | J14: https://drive.google.com/drive/folders/1g-8xtcXR4_Tt2ASFOMCsirDkrM7joNgF | K14: 栗原政史 | L14: 三好さん | M14: IT | N14: 概算提案フェーズ | O14: output_株式会社NEXT (1) | P14: 希望者名簿＿output_株式会社NEXT（修正版）.xlsx - Google スプレッドシート | Q14: 17 | R14: =Q14*80% -> 13.6 | S14: 112610895 | T14: =S14*0.5 -> 56305448 | AC14: =AB14+30 -> 30 | AE14: =AC14+60 -> 90 | AG14: =AE14+60 -> 150 | AI14: =T14*5% -> 2815272.4 | AJ14: =AG14+45 -> 195 | AM14: =T14*10% -> 5630544.8 | AN14: =AG14+30 -> 180
A15: 12 | B15: 46104 | D15: 尾崎 | E15: クライアント | F15: 東京 | G15: 板橋年金事務所 | I15: 株式会社セキムラ | J15: https://drive.google.com/drive/folders/1z25XIjyDhllINrsKEYVlWiFHFjuKTjdx?usp=sharing | K15: 新沼 直哉 | L15: 創作さん | M15: 医療機器メーカー | N15: 概算提案フェーズ | O15: 株式会社セキムラ | Q15: 71 | R15: =Q15*80% -> 56.8 | S15: 130448744 | T15: =S15*0.5 -> 65224372
A16: 13 | B16: 46093 | D16: 尾崎 | E16: クライアント | F16: 東京 | G16: 足立年金事務所 | I16: 株式会社HRfreaks | J16: https://drive.google.com/drive/folders/1FILKYriYaYciipHV1X14tll5bVwtijI0?usp=sharing | K16: 山根 弘行 | L16: 田中 | M16: 採用コンサルティング | N16: 書類取得フェーズ | R16: =Q16*80% -> 0 | T16: =S16*0.5 -> 0
A17: 14 | B17: 46096 | D17: 尾崎 | E17: クライアント | F17: 神奈川 | G17: 鶴見年金事務所 | I17: ハワイアンフォレスト株式会社 | J17: https://drive.google.com/drive/folders/1moDm_27z9F5Df0bKLgvQ-FyInvXg3kQW?usp=sharing | K17: 宮崎優 | L17: 花蜜 | M17: マッサージサロン | N17: 概算提案フェーズ | O17: output_ハワイアンフォレストSpa株式会社 | Q17: 59 | R17: =Q17*80% -> 47.2 | S17: 20312308 | T17: =S17*0.5 -> 10156154
A18: 15 | B18: 46096 | D18: 尾崎 | E18: クライアント | F18: 神奈川 | G18: 鶴見年金事務所 | I18: リラク＆ビューティー株式会社 | J18: https://drive.google.com/drive/folders/1moDm_27z9F5Df0bKLgvQ-FyInvXg3kQW?usp=sharing | K18: 宮崎優 | L18: 花蜜 | M18: 美容業 | N18: 概算提案フェーズ | O18: output_リラク＆ビューティー株式会社 | Q18: 109 | R18: =Q18*80% -> 87.2 | S18: 19410542 | T18: =S18*0.5 -> 9705271
A19: 17 | B19: 46100 | D19: 尾崎 | E19: クライアント | F19: 東京 | G19: 池袋年金事務所 | I19: エプコットソフトウェア | J19: https://drive.google.com/drive/folders/1_BYKwCfLzaW61QFGv4AVMJc_qvrWbG4q?usp=drive_link | K19: 山崎由介 | L19: 松本 | M19: システム開発 | N19: 概算提案フェーズ | O19: 株式会社エプコットソフトウェア | Q19: 169 | R19: =Q19*80% -> 135.2 | S19: 256372905 | T19: =S19*0.5 -> 1.2818645e+08
A20: 18 | B20: 46111 | D20: 尾崎 | E20: クライアント | F20: 岡山 | G20: 岡山西年金事務所 | I20: 株式会社スイッチ | J20: https://drive.google.com/drive/folders/1yFeFBOmzW7cbEi38oeYwKPM37bzStCNL | K20: 恒次明宏 | L20: VF | M20: web制作 | N20: 概算提案フェーズ | O20: 株式会社スイッチ | Q20: 49 | R20: =Q20*80% -> 39.2 | S20: 79758591 | T20: =S20*0.5 -> 39879296
A21: 19 | B21: 46111 | D21: 尾崎 | E21: クライアント | F21: 奈良 | G21: 奈良年金事務所 | I21: 株式会社ENAKAMA | J21: https://drive.google.com/drive/folders/17Ak1ZGq5iBWwGVZRatkc0wYuIddfBXsh | K21: 奥野 茂樹 | L21: VF | M21: 児童発達支援 | N21: 概算提案フェーズ | O21: 株式会社ENAKAM | Q21: 8 | R21: =Q21*80% -> 6.4 | S21: 9269769 | T21: =S21*0.5 -> 4634884.5
A22: 20 | B22: 46111 | D22: 尾崎 | E22: クライアント | F22: 東京 | G22: 奈良年金事務所 | I22: 株式会社K-FielD | J22: https://drive.google.com/drive/folders/1ZINJ3Ntsz76KgZfYTxRROuVQqPDiDgKE | K22: 兼利太樹 | L22: VF | M22: 不動産 | N22: 概算提案フェーズ | O22: 株式会社K-FielD | Q22: 71 | R22: =Q22*80% -> 56.8 | S22: 45145957 | T22: =S22*0.5 -> 22572978
A23: 21 | B23: 46111 | D23: 尾崎 | E23: クライアント | F23: 石川 | G23: 小松年金事務所 | I23: BOSS Group株式会社 | J23: https://drive.google.com/drive/folders/1Tu5OX6Nr0jwgUh1CS2X2ay0iCAcWtjLO | K23: 白江 誠一郎 | L23: VF | M23: 飲食 | N23: 概算提案フェーズ | O23: BOSS Group株式会社 | Q23: 9 | R23: =Q23*80% -> 7.2 | S23: 9325057 | T23: =S23*0.5 -> 4662528.5
A24: 22 | B24: 46113 | D24: 尾崎 | E24: クライアント | F24: 奈良 | G24: 大和高田年金事務所 | I24: 11.株式会社ベース | J24: https://drive.google.com/drive/folders/1xgSQpBfLYppF_z3elh05ibp5lPRCxdaN?usp=drive_link | K24: 京谷陽介 | L24: VF | M24: 不動産 | N24: 書類取得フェーズ | R24: =Q24*80% -> 0 | T24: =S24*0.5 -> 0
A25: 23 | B25: 46113 | D25: 尾崎 | E25: クライアント | F25: 広島 | G25: 広島東年金事務所 | I25: 4.株式会社クォリティプラス | J25: https://drive.google.com/drive/folders/1hWGWdqkHnUXHAzTh5dGcq7SH8YvybVAy?usp=drive_link | K25: 内平 雅也 | L25: VF | M25: 太陽光など | N25: 書類取得フェーズ | R25: =Q25*80% -> 0 | T25: =S25*0.5 -> 0
A26: 24 | B26: 46113 | D26: 尾崎 | E26: クライアント | F26: 大阪 | G26: 東大阪年金事務所 | I26: 15.株式会社豊見山組 | J26: https://drive.google.com/drive/folders/1cXR78HzITlsbCk4NUDemNWree9LErynY?usp=drive_link | K26: 豊見山亮 | L26: VF | M26: 左官工事 | N26: 書類取得フェーズ | R26: =Q26*80% -> 0 | T26: =S26*0.5 -> 0
A27: 25 | B27: 46113 | D27: 尾崎 | E27: クライアント | F27: 奈良 | G27: 奈良年金事務所 | I27: 14.株式会社エイチツーオー | J27: https://drive.google.com/drive/folders/1bk7reKFZYjMxSKlhvlzkCDb7ou5_oiiL?usp=drive_link | L27: VF | M27: 建設工事 | N27: 書類取得フェーズ | R27: =Q27*80% -> 0 | T27: =S27*0.5 -> 0
A28: 26 | B28: 46113 | D28: 尾崎 | E28: クライアント | F28: 大阪 | G28: 東大阪年金事務所 | I28: 13.豊栄水産株式会社 | J28: https://drive.google.com/drive/folders/1RxnBuGzvivC2ZTnZfG6c-kJTmem7zZFY?usp=drive_link | K28: 長町喜光 | L28: VF | M28: 水産業 | N28: 書類取得フェーズ | R28: =Q28*80% -> 0 | T28: =S28*0.5 -> 0
A29: 27 | B29: 46113 | D29: 尾崎 | E29: クライアント | F29: 京都 | G29: 中京年金事務所 | I29: 5.立生株式会社 | J29: https://drive.google.com/drive/folders/1MRd7KSTj-nsIhhljgU8xLMREQ4uL9JHk?usp=drive_link | K29: 佐藤靖之 | L29: VF | M29: HP制作 | N29: 書類取得フェーズ | R29: =Q29*80% -> 0 | T29: =S29*0.5 -> 0
A30: 28 | B30: 46113 | D30: 尾崎 | E30: クライアント | F30: 東京 | G30: 八王子年金事務所 | I30: 12.株式会社ソキュアス | J30: https://drive.google.com/drive/folders/1Hfm4-9Q4AEkcDGGJQoJ2SnOiwMxzrY_n?usp=drive_link | K30: 川近充 | L30: VF | M30: 帽子通販 | N30: 書類取得フェーズ | R30: =Q30*80% -> 0 | T30: =S30*0.5 -> 0
A31: 29 | B31: 46113 | D31: 尾崎 | E31: クライアント | F31: 京都 | G31: 京都南年金事務所 | I31: 10.株式会社YKS | J31: https://drive.google.com/drive/folders/1Af3KOefEMgCGg-hU2Cu7GmT6kXa5dDBD?usp=drive_link | K31: 小嶋康彦 | L31: VF | M31: 防水・止水工事など | N31: 書類取得フェーズ | R31: =Q31*80% -> 0 | T31: =S31*0.5 -> 0
A32: 30 | B32: 46113 | D32: 尾崎 | E32: クライアント | F32: 大阪 | G32: 平野年金事務所 | I32: 2.ケーツーエンジニアリング株式会社 | J32: https://drive.google.com/drive/folders/1ASlDv9YUUPXl7NTzt22lLJrP5K5MH3SS?usp=drive_link | K32: 秀平健二 | L32: VF | M32: オフィス機器導入 | N32: 書類取得フェーズ | R32: =Q32*80% -> 0 | T32: =S32*0.5 -> 0
A33: 31 | B33: 46113 | D33: 尾崎 | E33: クライアント | F33: 広島 | G33: 広島東年金事務所 | I33: 9.株式会社Sun.Assist | J33: https://drive.google.com/drive/folders/10RpyeMHTZFskyfzgWY3rER-7xQyNPw6L?usp=drive_link | K33: 岡野光壮 | L33: VF | M33: 太陽光など | N33: 書類取得フェーズ | R33: =Q33*80% -> 0 | T33: =S33*0.5 -> 0
A34: 32 | D34: 尾崎 | E34: クライアント | F34: 愛知 | G34: 鶴舞年金事務所 | I34: 株式会社Fit Founder | J34: 回収中 | K34: 八賀 晋太朗 | L34: 角田 | M34: 太陽光など | N34: 書類取得フェーズ | R34: =Q34*80% -> 0 | T34: =S34*0.5 -> 0
A35: 33 | R35: =Q35*80% -> 0 | T35: =S35*0.5 -> 0
A36: 34 | R36: =Q36*80% -> 0 | T36: =S36*0.5 -> 0
A37: 35 | R37: =Q37*80% -> 0 | T37: =S37*0.5 -> 0
A38: 36 | R38: =Q38*80% -> 0 | T38: =S38*0.5 -> 0
A39: 37 | R39: =Q39*80% -> 0
A40: 38 | R40: =Q40*80% -> 0
A41: 39 | R41: =Q41*80% -> 0
...

Sheet 進行中リスト
A1: 案件番号 | B1: 案件起票日 | C1: 名前 | D1: AS担当者 | E1: 顧客区分 | F1: 企業名 | G1: 紹介者 | H1: 業種 | I1: ステータス | J1: 最大申請人数 | K1: 想定申請人数 | L1: 想定還付金額 | M1: 確定還付金額 | N1: 弊社想定売上(※開発費) | O1: 確定想定売上(※開発費) | P1: 想定代理店売上 | Q1: 確定代理店売上 | R1: 次のアクション | S1: 次に連絡する日 | T1: 初回商談日 | U1: 想定申請日 | V1: 確定申請日 | W1: 想定充当通知日 | X1: 確定充当通知日 | Y1: 想定還付日 | Z1: 確定還付日 | AA1: 想定伊藤先生報酬額 | AB1: 想定伊藤先生支払日 | AC1: 確定伊藤先生報酬額 | AD1: 確定伊藤先生支払日 | AE1: 想定弊社報酬額 | AF1: 想定弊社支払日 | AG1: 確定弊社報酬額 | AH1: 確定弊社支払日
A2: 1 | B2: 46064 | C2: サンプル | D2: 宮原 | E2: クライアント | F2: サンプル株式会社 | H2: 建設業 | I2: 書類取得フェーズ | J2: 申請可能人数(申請人数) | R2: 申請フェーズ | S2: 46064 | T2: 46064 | U2: =T2+30 -> 46094 | W2: =U2+60 -> 46154 | Y2: =W2+60 -> 46214 | AA2: =L2*10% -> 0 | AB2: =Y2+45 -> 46259 | AE2: =L2*10% -> 0 | AF2: =Y2+30 -> 46244
A3: 2 | B3: 46069 | D3: 鈴木 | E3: クライアント | F3: 株式会社 アポロホールディングス | H3: 美容業 | I3: 概算提案フェーズ | J3: 107 | K3: =J3*50% -> 53.5 | L3: 110541008 | N3: =L3*0.2*0.8 -> 17686561 | P3: =L3*0.1 -> 11054101 | U3: =T3+30 -> 30 | W3: =U3+60 -> 90 | Y3: =W3+60 -> 150 | AA3: =L3*10% -> 11054101 | AB3: =Y3+45 -> 195 | AE3: =L3*10% -> 11054101 | AF3: =Y3+30 -> 180
A4: 3 | B4: 46069 | D4: 鈴木 | E4: クライアント | F4: 株式会社 アポロプランニング | H4: 観光業 | I4: 概算提案フェーズ | J4: 354 | K4: =J4*80% -> 283.2 | L4: 353957644 | N4: =L4*0.2*0.8 -> 56633223 | P4: =L4*0.1 -> 35395764 | U4: =T4+30 -> 30 | W4: =U4+60 -> 90 | Y4: =W4+60 -> 150 | AA4: =L4*10% -> 35395764 | AB4: =Y4+45 -> 195 | AE4: =L4*10% -> 35395764 | AF4: =Y4+30 -> 180
A5: 4 | B5: 46069 | D5: 尾崎 | E5: クライアント | F5: 株式会社 琴美建設 | H5: 建設業 | I5: 概算提案フェーズ | J5: 17 | K5: =J5*80% -> 13.6 | L5: 6655839 | N5: =L5*0.2*0.8 -> 1064934.2 | P5: =L5*0.1 -> 665583.9 | U5: =T5+30 -> 30 | W5: =U5+60 -> 90 | Y5: =W5+60 -> 150 | AA5: =L5*10% -> 665583.9 | AB5: =Y5+45 -> 195 | AE5: =L5*10% -> 665583.9 | AF5: =Y5+30 -> 180
A6: 5 | B6: 46069 | D6: 飯塚 | E6: クライアント | F6: 株式会社RISE様 | H6: 美容業 | I6: 申請フェーズ | J6: 23 | K6: =J6*80% -> 18.4 | L6: 30251059 | N6: =L6*0.2*0.8 -> 4840169.4 | P6: =L6*0.1 -> 3025105.9 | U6: =T6+30 -> 30 | W6: =U6+60 -> 90 | Y6: =W6+60 -> 150 | AA6: =L6*10% -> 3025105.9 | AB6: =Y6+45 -> 195 | AE6: =L6*10% -> 3025105.9 | AF6: =Y6+30 -> 180
A7: 6 | B7: 46069 | D7: 鈴木 | E7: クライアント | F7: 株式会社ＭａｉｎＣ様 | H7: 飲食業 | I7: 概算提案フェーズ | J7: 15 | K7: =J7*80% -> 12 | L7: 10826393 | N7: =L7*0.2*0.8 -> 1732222.9 | P7: =L7*0.1 -> 1082639.3 | U7: =T7+30 -> 30 | W7: =U7+60 -> 90 | Y7: =W7+60 -> 150 | AA7: =L7*10% -> 1082639.3 | AB7: =Y7+45 -> 195 | AE7: =L7*10% -> 1082639.3 | AF7: =Y7+30 -> 180
A8: 7 | B8: 46069 | D8: 尾崎 | E8: クライアント | F8: 株式会社バリューフロンティア | H8: 営業 | I8: 申請フェーズ | J8: 52 | K8: =J8*80% -> 41.6 | L8: 35304064 | N8: =L8*0.2*0.8 -> 5648650.2 | P8: =L8*0.1 -> 3530406.4 | U8: =T8+30 -> 30 | W8: =U8+60 -> 90 | Y8: =W8+60 -> 150 | AA8: =L8*10% -> 3530406.4 | AB8: =Y8+45 -> 195 | AE8: =L8*10% -> 3530406.4 | AF8: =Y8+30 -> 180
A9: 8 | B9: 46069 | D9: 尾崎 | E9: クライアント | F9: 株式会社Good Work Japan | H9: 人材業 | I9: 申請フェーズ | J9: 1945 | K9: =J9*20% -> 389 | U9: =T9+30 -> 30 | W9: =U9+60 -> 90 | Y9: =W9+60 -> 150 | AA9: =L9*10% -> 0 | AB9: =Y9+45 -> 195 | AE9: =L9*10% -> 0 | AF9: =Y9+30 -> 180
A10: 9 | B10: 46080 | D10: 尾崎 | E10: クライアント | F10: 株式会社ＮＥＸＴ | G10: 三好様 | H10: 物販 | I10: 書類取得フェーズ | K10: =J10*80% -> 0 | U10: =T10+30 -> 30 | W10: =U10+60 -> 90 | Y10: =W10+60 -> 150 | AA10: =L10*10% -> 0 | AB10: =Y10+45 -> 195 | AE10: =L10*10% -> 0 | AF10: =Y10+30 -> 180
A11: 10 | B11: 46078 | D11: 尾崎 | E11: クライアント | F11: ジェイシップセントラル株式会社 | H11: 人材業 | I11: 書類取得フェーズ | K11: =J11*80% -> 0 | U11: =T11+30 -> 30 | W11: =U11+60 -> 90 | Y11: =W11+60 -> 150 | AA11: =L11*10% -> 0 | AB11: =Y11+45 -> 195 | AE11: =L11*10% -> 0 | AF11: =Y11+30 -> 180
A12: 11 | B12: 46070 | D12: 尾崎 | E12: クライアント | F12: 一般社団法人LIEN | G12: 植倉様 | H12: 美容業 | I12: 概算提案フェーズ | K12: =J12*80% -> 0 | U12: =T12+30 -> 30 | W12: =U12+60 -> 90 | Y12: =W12+60 -> 150 | AA12: =L12*10% -> 0 | AB12: =Y12+45 -> 195 | AE12: =L12*10% -> 0 | AF12: =Y12+30 -> 180
A13: 12 | B13: 46079 | D13: 尾崎 | E13: クライアント | F13: aspo株式会社 | G13: VF | I13: 書類取得フェーズ | K13: =J13*80% -> 0 | U13: =T13+30 -> 30 | W13: =U13+60 -> 90 | Y13: =W13+60 -> 150 | AA13: =L13*10% -> 0 | AB13: =Y13+45 -> 195 | AE13: =L13*10% -> 0 | AF13: =Y13+30 -> 180
A14: 13 | K14: =J14*80% -> 0 | U14: =T14+30 -> 30 | W14: =U14+60 -> 90 | Y14: =W14+60 -> 150 | AA14: =L14*10% -> 0 | AB14: =Y14+45 -> 195 | AE14: =L14*10% -> 0 | AF14: =Y14+30 -> 180
A15: 14 | K15: =J15*80% -> 0 | U15: =T15+30 -> 30 | W15: =U15+60 -> 90 | Y15: =W15+60 -> 150 | AA15: =L15*10% -> 0 | AB15: =Y15+45 -> 195 | AE15: =L15*10% -> 0 | AF15: =Y15+30 -> 180
A16: 15 | K16: =J16*80% -> 0 | U16: =T16+30 -> 30 | W16: =U16+60 -> 90 | Y16: =W16+60 -> 150 | AA16: =L16*10% -> 0 | AB16: =Y16+45 -> 195 | AE16: =L16*10% -> 0 | AF16: =Y16+30 -> 180
A17: 16 | K17: =J17*80% -> 0 | U17: =T17+30 -> 30 | W17: =U17+60 -> 90 | Y17: =W17+60 -> 150 | AA17: =L17*10% -> 0 | AB17: =Y17+45 -> 195 | AE17: =L17*10% -> 0 | AF17: =Y17+30 -> 180
A18: 17 | K18: =J18*80% -> 0 | U18: =T18+30 -> 30 | W18: =U18+60 -> 90 | Y18: =W18+60 -> 150 | AA18: =L18*10% -> 0 | AB18: =Y18+45 -> 195 | AE18: =L18*10% -> 0 | AF18: =Y18+30 -> 180
A19: 18 | K19: =J19*80% -> 0 | U19: =T19+30 -> 30 | W19: =U19+60 -> 90 | Y19: =W19+60 -> 150 | AA19: =L19*10% -> 0 | AB19: =Y19+45 -> 195 | AE19: =L19*10% -> 0 | AF19: =Y19+30 -> 180
A20: 19 | K20: =J20*80% -> 0 | U20: =T20+30 -> 30 | W20: =U20+60 -> 90 | Y20: =W20+60 -> 150 | AA20: =L20*10% -> 0 | AB20: =Y20+45 -> 195 | AE20: =L20*10% -> 0 | AF20: =Y20+30 -> 180
A21: 20 | K21: =J21*80% -> 0 | U21: =T21+30 -> 30 | W21: =U21+60 -> 90 | Y21: =W21+60 -> 150 | AA21: =L21*10% -> 0 | AB21: =Y21+45 -> 195 | AE21: =L21*10% -> 0 | AF21: =Y21+30 -> 180
A22: 21 | K22: =J22*80% -> 0 | U22: =T22+30 -> 30 | W22: =U22+60 -> 90 | Y22: =W22+60 -> 150 | AA22: =L22*10% -> 0 | AB22: =Y22+45 -> 195 | AE22: =L22*10% -> 0 | AF22: =Y22+30 -> 180
A23: 22 | K23: =J23*80% -> 0 | U23: =T23+30 -> 30 | W23: =U23+60 -> 90 | Y23: =W23+60 -> 150 | AA23: =L23*10% -> 0 | AB23: =Y23+45 -> 195 | AE23: =L23*10% -> 0 | AF23: =Y23+30 -> 180
A24: 23 | K24: =J24*80% -> 0 | U24: =T24+30 -> 30 | W24: =U24+60 -> 90 | Y24: =W24+60 -> 150 | AA24: =L24*10% -> 0 | AB24: =Y24+45 -> 195 | AE24: =L24*10% -> 0 | AF24: =Y24+30 -> 180
A25: 24 | K25: =J25*80% -> 0 | U25: =T25+30 -> 30 | W25: =U25+60 -> 90 | Y25: =W25+60 -> 150 | AA25: =L25*10% -> 0 | AB25: =Y25+45 -> 195 | AE25: =L25*10% -> 0 | AF25: =Y25+30 -> 180
... A101: 100 | K101: =J101*80% -> 0 | U101: =T101+30 -> 30 | W101: =U101+60 -> 90 | Y101: =W101+60 -> 150 | AA101: =L101*10% -> 0 | AB101: =Y101+45 -> 195 | AE101: =L101*10% -> 0 | AF101: =Y101+30 -> 180

Sheet 伊藤先生質問予定
A1: 記載日 | B1: 質問日 | C1: 質問 | D1: 回答
A2: 46037 | B2: 46043 | C2: 外国人労働者も対象なのか | D2: 可能 源泉所得税を20%→10%に下げられる
C3: 雇用契約と業務委託の契約を明確にしていくロジックだが役員や社長分が還付されるのはどんな内容か
C4: テレグラムに移行して良いか
C5: 従業員の同意書 | D5: /同意書/意識表明書
C6: 企業と伊藤先生が結ぶ契約書 どゆこと？ | D6: 業務委託報酬/職能別の資料作成費用
C7: 報酬を20%もらうと思うのですが、人事制度見直しを例えばバリューがstellaに依頼する場合の契約書が必要だと思うのですがどうですか
C8: 源泉所得税と支払っている金額は、本来取りすぎているので、社員が確定申告後、還付もしくは追加徴税は発生しますか？ →これを聞かれた際の対応を明確にする
C9: ・すでに年金もらってる方達が給料見直しするとどうなるのか？ →現在もらっている年金に影響があるのか？
C10: 概算を出した後の業務の明確化
C11: 今後、給与+報酬の従業員の確定申告の必要性とその場合の対応方法は
C12: 合意書を最適化させるにあたってのポイント
C13: 未来の業務委託費用の支払いは同一企業で問題ないのか。
A14: 46052 | C14: ご質問の件ですが、在留資格「技術・人文知識・国際業務（いわゆる技人国）」につきましては、原則として業務委託契約での就業は認められておりません。 技人国は「雇用契約」を前提とした在留資格であり、指揮命令下での業務・安定的な給与支払いが要件となるため、業務委託（成果報酬・裁量労働）との併用、いわゆる**「一部社員・一部業務委託」という形態も、実務上は認められない扱い**となります。 なお、業務委託が可能なのは永住者、日本人の配偶者等、定住者などの身分系在留資格に限られます。 そのため、技人国の方を起用する場合は、雇用契約（社員・契約社員等）に一本化する形が安全となります。
A15: 46055 | C15: 基本給を減額することにより標準報酬月額が下がるので産休手当も必然的に下がると思いますが、その場合昨年度の基本給だけ下げない方法も可能でしょうか。

Sheet 登記前の経費シート
A1: 日付 | B1: 名目 | C1: 金額 | D1: 備考
A2: 46037 | B2: 03plus契約料 | C2: 25446 | D2: 尾崎さんの楽天銀行で振り込み ※法人登記後変更する
A3: 46037 | B3: クラウドサイン | C3: 11000 | D3: 初期費用：0円 月額費用：10,000円（税込 11,000円） 年額費用：120,000円（税込 132,000円） 書類送信費用：1件あたり200円（税込 220円） ※毎月、月額費用と当該月の送信件数に応じた書類送信費用をお支払いいただきます
A4: 46045 | B4: 一般社団法人設立サポート費用 | C4: 120000 | D4: 【明細】 ■ 報酬額 ・一般社団法人設立登記費用（司法書士） 数量：1 単価：90,000円 金額：90,000円 ・値引き（顧問契約分） 数量：1 単価：-90,000円 金額：-90,000円 ・定款作成費用 数量：1 単価：0円 金額：0円 ■ 登録免許税又は印紙等費用 ・一般社団法人設立登録免許税 数量：1 単価：60,000円 金額：60,000円 ・定款印紙代 数量：1 単価：40,000円 金額：40,000円 ・電子定款による値引き 数量：1 単価：-40,000円 金額：-40,000円 ・定款認証費用（公証役場） 数量：1 単価：52,000円 金額：52,000円 ・登記事項証明書（1通） 数量：1 単価：500円 金額：500円 ・印鑑証明書（1通） 数量：1 単価：500円 金額：500円 ■ その他費用 ・郵送費 数量：1 単価：2,150円 金額：2,150円 ・法人印鑑作成費用（代表印・銀行印・角印・ケース） 数量：1 単価：5,860円 金額：5,860円
A5: 46053 | B5: クラウドサイン送信費用 | C5: 12980 | D5: 送信合計 59 ×220円
A6: 46077 | B6: 03plus1月分費用 | C6: 3942
A7: 46053 | B7: 従業員動画作成費用(外注費用) | C7: 60,000円 | D7: 大村に正確な数字を確認する

Sheet スターターキット
A1: 📦 スターターキット完全一覧
A3: 事業スタートに必要な全ての書類・ツール・資料を完全網羅
A4: 現状14項目 → 提案82項目（合計）
A6: カテゴリ | B6: No | C6: 項目名 | D6: 形式 | E6: 重要度 | F6: ステータス | G6: 備考 | H6: 備考
A8: 【現状の項目】14項目
A10: Webサイト
B11: 1 | C11: 会社HP | D11: Web | E11: ★★★ | F11: □
A12: 契約・法務書類（7項目）
B13: 2 | C13: 組合員契約書 | D13: Word/PDF | E13: ★★★ | F13: □ | G13: 弁護士チェック必須 | H13: https://docs.google.com/document/d/10-VrAL2LJeN1zCDoCIbBPoYFEctPAaMmkyVrnG474dk/edit?tab=t.0 | I13: https://docs.google.com/document/d/1iPK2y4dy5PZvpkpI3fK8S4_A0RbQg3WYXCTIzGvqRJc/edit?usp=sharing
B14: 3 | C14: 組合規定 | D14: Word/PDF | E14: ★★★ | F14: □ | H14: https://docs.google.com/document/d/1ktuLrfRa47YU0trBCXB_K1QkfWXXlmhGN0Co245UtGE/edit?tab=t.0
B15: 4 | C15: 代理店契約書 | D15: Word/PDF | E15: ★★★ | F15: □ | G15: バリュー社3%条件含む | H15: https://docs.google.com/document/d/1FgSSlzyvZcQ2Zw8jPO869CIqX9X4KhHyJU2luncwQqo/edit?usp=sharing
B16: 5 | C16: 機密情報および個人情報の取扱いに関する同意書 | D16: Word/PDF | E16: ★★★ | F16: □ | H16: https://docs.google.com/document/d/1PmYDTBTh2e0Qb7kZtHiWXCQZluRcKGcn3B_cuJY5qms/edit?usp=sharing
B17: 6 | C17: 反社会的勢力の排除に関する誓約書 | D17: Word/PDF | E17: ★★★ | F17: □ | H17: https://docs.google.com/document/d/1SJdWNy1dzF9gIQoPVrMiZ2o6FjfPcZItKQpubZCWVuQ/edit?usp=sharing
B18: 7 | C18: 業務委託契約書 | D18: Word/PDF | E18: ★★★ | F18: □ | G18: 従業員用 | H18: https://docs.google.com/document/d/17HRwAb2JJMneLaPYGED_-ZfcxzHG5ddRTvHVYje4D9Q/edit?tab=t.0
B19: 8 | C19: 従業員同意書 | D19: Word/PDF | E19: ★★★ | F19: □ | G19: 人事労務評価制度への同意 | H19: https://docs.google.com/document/d/1Ml6mlJ0yM4VNEMLQ66PGF_EO_5ruKDx41LtUK6s3jkI/edit?tab=t.0
A20: 教育・説明資料（4項目）
B21: 9 | C21: 従業員説明動画(LLS) | D21: MP4 | E21: ★★★ | F21: □ | G21: LMSで自動生成
B22: 10 | C22: 営業資料(組合入会前) | D22: PPT/PDF | E22: ★★★ | F22: □ | H22: https://www.canva.com/design/DAG-esrNdQo/pa4F3wjPArqqaN8-T72ZTA/view?utm_content=DAG-esrNdQo&utm_campaign=designshare&utm_medium=link2&utm_source=uniquelinks&utlId=h115d8fd5a7
B23: 11 | C23: トークスクリプト | D23: Word/PDF | E23: ★★★ | F23: □
B24: 12 | C24: 概要説明資料 | D24: PPT/PDF | E24: ★★★ | F24: □ | H24: https://www.canva.com/design/DAG-D0UMy1s/Gt3ICNEMs3JH1-oaBb4v2A/view?utm_content=DAG-D0UMy1s&utm_campaign=designshare&utm_medium=link2&utm_source=uniquelinks&utlId=hec288880b9
A25: 業務書類（2項目）
B26: 13 | C26: 還付金請求書 | D26: Excel/PDF | E26: ★★★ | F26: □
B27: 14 | C27: 必要書類提出フォーム | D27: Excel/Web | E27: ★★★ | F27: □ | G27: Googleフォーム等 | H27: https://yjpv5pf0p3pj.jp.larksuite.com/share/base/form/shrjp1ksluRzpVbtKSG0VwOaTYe
A30: 【追加提案項目】68項目
A32: 1. 年金事務所申請関連書類（6項目）
B33: 15 | C33: 過誤申立書フォーマット | D33: Word/Excel | E33: ★★★ | F33: □ | G33: 年金事務所提出用
B34: 16 | C34: 人事評価制度変更届出書 | D34: Word/PDF | E34: ★★★ | F34: □
B35: 17 | C35: 弁護士意見書ひな形 | D35: Word/PDF | E35: ★★★ | F35: □ | G35: 伊藤先生
B36: 18 | C36: 新旧制度比較表フォーマット | D36: Excel/Word | E36: ★★★ | F36: □ | G36: 伊藤先生
B37: 19 | C37: 業務実態を示す資料フォーマット | D37: Word/PDF | E37: ★★★ | F37: □ | G37: 伊藤先生
B38: 20 | C38: 年金事務所提出書類チェックリスト | D38: Excel | E38: ★★★ | F38: □ | G38: 伊藤先生
A39: 2. シミュレーション・試算ツール（5項目）
B40: 21 | C40: 簡易シミュレーター（Excel） | D40: Excel | E40: ★★★ | F40: □ | G40: 営業用 | H40: https://st022187.static.jp/d/social-insurance-simulator/
B41: 22 | C41: 詳細シミュレーター（Excel） | D41: Excel | E41: ★★★ | F41: □ | G41: 精密試算用 | H41: https://docs.google.com/spreadsheets/d/1mE2582OK3Sy8POqKTShjK9eSLI3cc2gB4zhqkf-syFI/edit?usp=sharing
B42: 23 | C42: 個別従業員シミュレーション資料 | D42: Excel | E42: ★★★ | F42: □ | G42: 従業員説明会用
B43: 24 | C43: 還付金グラフ自動生成ツール | D43: Excel | E43: ★★ | F43: □ | G43: グラフ自動作成
B44: 25 | C44: 見積書自動生成ツール | D44: Excel | E44: ★★★ | F44: □ | G44: 今週中必須
A45: 3. 営業支援ツール（9項目）
B46: 26 | C46: LINE公式アカウント設定ガイド | D46: PDF | E46: ★★★ | F46: □
B47: 27 | C47: プロライン導線設定マニュアル | D47: PDF | E47: ★★★ | F47: □
...

Sheet BizDev
A1: ✅ 社会保険料適正化サービス BizDev チェックリスト
A2: このチェックリストは、社会保険料適正化サービスの事業健全性を189項目で評価します。
A4: カテゴリ | B4: サブカテゴリ | C4: チェック項目 | D4: 説明・基準 | E4: 優先度 | F4: 確認頻度 | G4: 担当/責任 | I4: 完了
A5: ガバナンス・組織 | B5: コンプラ | C5: 反社チェックフローがあるか | D5: 顧客・パートナーの反社チェックを実施 | E5: S | F5: 月次 | G5: 管理部
A6: ガバナンス・組織 | B6: コンプラ | C6: 社会保険労務士との顧問契約があるか | D6: 適正化サービスの法的妥当性を常時確認 | E6: S | F6: 契約中 | G6: 経営層
A7: ガバナンス・組織 | B7: コンプラ | C7: 税理士との顧問契約があるか | D7: 税務面での適法性を常時確認 | E7: S | F7: 契約中 | G7: 経営層
A8: ガバナンス・組織 | B8: 内部統制 | C8: 稟議・承認が電子化されているか | D8: 契約承認フローの透明性確保 | E8: A | F8: 月次 | G8: 管理部
A9: ガバナンス・組織 | B9: 内部統制 | C9: 内部通報/ホットラインの仕組みがあるか | D9: 不正防止の仕組み | E9: A | F9: 四半期 | G9: 管理部
A10: ガバナンス・組織 | B10: 情報共有 | C10: 経営数値が幹部に共有されているか | D10: 売上・契約数・還付額などKGI/KPI | E10: S | F10: 週次 | G10: 経営層
A11: ガバナンス・組織 | B11: 情報共有 | C11: 議事録・決定事項がアーカイブされているか | D11: 経営会議・営業会議の記録保存 | E11: A | F11: 月次 | G11: 管理部
A12: ガバナンス・組織 | B12: 意思決定 | C12: 経営会議の開催頻度と議題が固定されているか | D12: 週次または月次で定例化 | E12: S | F12: 週次 | G12: 経営層
A13: ガバナンス・組織 | B13: 意思決定 | C13: 重要決裁の権限規程があるか | D13: 契約金額・割引率などの決裁ライン | E13: S | F13: 四半期 | G13: 経営層
A14: ガバナンス・組織 | B14: 組織設計 | C14: RACIで責任所在が明確か | D14: 営業・CS・伊藤先生側・税理士の役割明確化 | E14: A | F14: 四半期 | G14: 経営層
A15: ガバナンス・組織 | B15: 組織設計 | C15: 組織図と役割が最新化されているか | D15: 営業5名→20名への拡大計画と連動 | E15: A | F15: 月次 | G15: 人事
A16: ガバナンス・組織 | B16: KPI設計 | C16: KPIを週次/月次でモニタリングする場があるか | D16: 商談数・成約数・還付実行数など | E16: S | F16: 週次 | G16: 営業部長
A17: ガバナンス・組織 | B17: KPI設計 | C17: 事業KGI→事業KPI→現場KPIがピラミッドでつながっているか | D17: 売上3億→契約30社→商談150社 | E17: S | F17: 月次 | G17: 経営層
A18: ガバナンス・組織 | B18: ミッション/ビジョン | C18: 存在意義（Why）が一文で定義されているか | D18: 例: 企業と従業員の両方を豊かにする | E18: S | F18: 年次 | G18: 経営層 | H18: 中小企業が“知らないことで損をし続ける構造”を、仕組みで改善する | I18: 完了
A19: ガバナンス・組織 | B19: ミッション/ビジョン | C19: 3年ビジョンを数値とストーリーで示しているか | D19: 3年後: 売上10億円、契約100社など | E19: S | F19: 年次 | G19: 経営層 | H19: 1年後：売上25.2億、粗利12,6億、契約420社 | I19: 完了
A20: ガバナンス・組織 | B20: ミッション/ビジョン | C20: MVVが組織に共有・浸透しているか | D20: 採用・評価・研修に連動しているか | E20: A | F20: 半期 | G20: 人事
A21: ガバナンス・組織 | B21: 市場・ポジショニング | C21: 主要市場の定義が明確か（業界・エリア・顧客規模） | D21: 従業員10-50名、年間給与総額5000万円以上 | E21: S | F21: 四半期 | G21: 営業部長 | H21: 日本全体の社会保険料収入80.1兆
A22: ガバナンス・組織 | B22: 市場・ポジショニング | C22: 競合マップを四象限で描けるか | D22: 遡及期間×成果報酬率で競合分析 | E22: S | F22: 四半期 | G22: 営業部長
A23: ガバナンス・組織 | B23: 市場・ポジショニング | C23: 自社の差別化ポイント（USP）が3つ以内で話せるか | D23: ①5年遡及 ②初期費用0円 ③実態構築支援 | E23: S | F23: 月次 | G23: 営業部長
A24: 営業・マーケティング | B24: リード獲得 | C24: 無料診断の提供体制があるか | D24: 算定基礎届から還付見込額を無料試算 | E24: S | F24: 毎日 | G24: 営業
A25: 営業・マーケティング | B25: リード獲得 | C25: 紹介営業の仕組みがあるか | D25: 税理士・伊藤先生側・既存顧客からの紹介 | E25: S | F25: 月次 | G25: 営業部長
A26: 営業・マーケティング | B26: リード獲得 | C26: セミナー・説明会を定期開催しているか | D26: 経営者向け社会保険料削減セミナー | E26: A | F26: 月次 | G26: 営業
A27: 営業・マーケティング | B27: リード獲得 | C27: Web広告（Google/Facebook）を運用しているか | D27: 「社会保険料 削減」などのキーワード | E27: B | F27: 月次 | G27: マーケ
A28: 営業・マーケティング | B28: 営業プロセス | C28: 営業トークスクリプトが整備されているか | D28: 5シーン別の台本を全員が暗記 | E28: S | F28: 四半期 | G28: 営業部長
A29: 営業・マーケティング | B29: 営業プロセス | C29: 還付金シミュレーターを商談で使っているか | D29: Excel使用、リアルタイム計算 | E29: S | F29: 毎日 | G29: 営業
A30: 営業・マーケティング | B30: 営業プロセス | C30: 提案書テンプレートがあるか | D30: 還付見込額・配分・スケジュールを記載 | E30: A | F30: 月次更新 | G30: 営業部長
A31: 営業・マーケティング | B31: 営業プロセス | C31: 成約後の手続きフローが明文化されているか | D31: 契約→資料収集→伊藤先生側連携→実行 | E31: S | F31: 四半期 | G31: CS
A32: 営業・マーケティング | B32: 営業プロセス | C32: クロージング時の価格交渉ルールがあるか | D32: 成果報酬15-20%の裁量範囲を明確化 | E32: A | F32: 四半期 | G32: 営業部長
A33: 営業・マーケティング | B33: 案件管理 | C33: CRMで案件進捗を管理しているか | D33: リード→商談→成約→実行の各段階 | E33: S | F33: 毎日 | G33: 営業部長
... A37: 法務・コンプライアンス | B37: 契約書 | C37: 業務委託契約書のひな型があるか | D37: 実態構築用の委託契約テンプレート | E37: S | F37: 年次見直し | G37: 法務
A38: 法務・コンプライアンス | B38: 契約書 | C38: 組合規約が整備されているか | D38: 組合員の権利義務を明文化 | E38: S | F38: 年次見直し | G38: 法務 | I38: 完了
A39: 法務・コンプライアンス | B39: 契約書 | C39: 秘密保持契約（NDA）があるか | D39: 算定基礎届など機密情報の取扱い | E39: S | F39: 個別締結 | G39: 法務 | I39: 完了
A40: 法務・コンプライアンス | B40: 実態構築 | C40: 業務委託の実態基準が文書化されているか | D40: 月○回の業務実施、報告書作成など | E40: S | F40: 四半期 | G40: 伊藤先生側
A41: 法務・コンプライアンス | B41: 実態構築 | C41: 業務日報・報告書のテンプレートがあるか | D41: 実態の証跡として保管 | E41: S | F41: 毎月 | G41: CS
A42: 法務・コンプライアンス | B42: 実態構築 | C42: 業務実施の写真・動画を記録しているか | D42: 調査時の証拠として活用 | E42: A | F42: 毎月 | G42: CS
A43: 法務・コンプライアンス | B43: 実態構築 | C43: 実態構築チェックリストがあるか | D43: 10項目以上の確認項目 | E43: S | F43: 案件ごと | G43: 伊藤先生側
A44: 法務・コンプライアンス | B44: 調査対応 | C44: 年金事務所調査への対応マニュアルがあるか | D44: 調査時の説明・資料提出フロー | E44: S | F44: 年次見直し | G44: 伊藤先生側
...

Sheet 営業管理売上見込
A1: 月 | B1: 月間獲得件数 | C1: 累計獲得件数 | D1: 日間獲得数
A2: 1月 | B2: 6 | C2: 6 | D2: =B2/30 -> 0.2
A3: 2月 | B3: 9 | C3: 15 | D3: =B3/30 -> 0.3
A4: 3月 | B4: 12 | C4: 27 | D4: =B4/30 -> 0.4
A5: 4月 | B5: 15 | C5: 42 | D5: =B5/30 -> 0.5
A6: 5月 | B6: 18 | C6: 60 | D6: =B6/30 -> 0.6
A7: 6月 | B7: 23 | C7: 83 | D7: =B7/30 -> 0.76666667
A8: 7月 | B8: 29 | C8: 112 | D8: =B8/30 -> 0.96666667
A9: 8月 | B9: 36 | C9: 148 | D9: =B9/30 -> 1.2
A10: 9月 | B10: 46 | C10: 194 | D10: =B10/30 -> 1.5333333
A11: 10月 | B11: 56 | C11: 250 | D11: =B11/30 -> 1.8666667
A12: 11月 | B12: 64 | C12: 314 | D12: =B12/30 -> 2.1333333
A13: 12月 | B13: 106 | C13: 420 | D13: =B13/30 -> 3.5333333

Sheet 開発要件定義
A1: あなたは、公的資金（補助金・助成金・行政連携案件）における
A2: システム開発要件定義書の作成を専門とするITコンサルタント兼PMです。
A3: 以下の【簡易要件定義】をもとに、
A4: 「公的資金開発に耐えうる正式な要件定義書」を作成してください。
A5: ■ 要求水準
A6: - 開発会社にそのまま見積・設計依頼ができるレベル
A7: - 補助金・公的資金の審査で指摘されない論理性・網羅性
A8: - 業務要件／機能要件／非機能要件を明確に分離
A9: - 曖昧な表現は避け、誰が読んでも同じ解釈になること
A10: - 「やること／やらないこと（スコープ）」を明確にすること
A11: ■ アウトプット形式
A12: 以下の章立てで、**日本語・テキスト形式**で作成してください。
... A93: - 公的資金案件として説明責任が果たせる文章にすること

Sheet 00_マスター目次
A1: 📋 社会保険料適正化サービス 完全統合版 v23
A2: 〜 実務で即使える完全マニュアル 〜
A3: 【v23の特徴】
A4: ✓ 全ナレッジを完全統合（情報欠落ゼロ）
A5: ✓ 実務フロー重視の構成
A6: ✓ 役割別最適化
A7: ✓ 視認性を最大化
A8: ✓ 9シートで完結
A11: No | B11: シート名 | C11: 内容 | D11: 対象者
A12: 00 | B12: マスター目次 | C12: ナビゲーション・クイックスタート | D12: 全員
A13: 01 | B13: 事業コンセプト完全理解 | C13: 成立理由・1顧客7収入・2年計画・市場 | D13: 経営者・営業
A14: 02 | B14: 法的基盤と防御戦略 | C14: 使用従属性・4層防御・伊藤先生・リスク | D14: 経営者・営業
A15: 03 | B15: 営業完全マニュアル | C15: 9ステップ・トーク・反論処理50 | D15: 営業・代理店
A16: 04 | B16: シミュレーター＆ツール | C16: 簡易版・詳細版・グラフ・計算式 | D16: 営業・CS
A17: 05 | B17: CS実務ガイド | C17: オンボーディング・案件管理・品質 | D17: CS
A18: 06 | B18: 書類・契約テンプレート | C18: 契約書・申請書・同意書・説明資料 | D18: CS・バックオフィス
A19: 07 | B19: 組織運営・拡大戦略 | C19: 代理店・KPI・協会運営・研修 | D19: 経営者・管理者
A20: 08 | B20: リファレンス | C20: 用語・法律・FAQ・連絡先・履歴 | D20: 全員
A22: 【5秒でスタート】
A23: 🎯 経営者の方 | B23: → 01 → 02 → 07 | C23: 事業理解・法的基盤・組織戦略
A24: 💼 営業担当の方 | B24: → 01 → 03 → 04 | C24: コンセプト・営業術・ツール使用
A25: 🎧 CS担当の方 | B25: → 05 → 04 → 06 | C25: 実務手順・ツール・書類管理
A26: 📊 バックオフィスの方 | B26: → 06 → 07 | C26: 書類・KPI管理
A27: 🤝 代理店の方 | B27: → 01 → 02 → 03 | C27: コンセプト・法的理解・営業術
A29: 【今週やること】
A31: □ | B31: 01を読んで事業コンセプトを理解（15分）
A32: □ | B32: 02で法的基盤を確認（20分）
A33: □ | B33: 03で営業9ステップを習得（30分）
A34: □ | B34: 04でシミュレーターを試用（10分）
A35: □ | B35: 自分の役割のシートを精読（30分）

Sheet 01_事業コンセプト完全理解
A1: 💡 事業コンセプト完全理解
A2: なぜ成立するか・1顧客7収入・2年計画・市場機会
A3: なぜ成立するか・1顧客7収入モデル・2年計画を完全理解
A4: ━━━━━━━━━━━━━━━━━━━━━━━━━━━━━━━━━━━━━━━━━━━━━━━━━━
A5: 第1章: なぜこのビジネスが成立するのか
A6: ━━━━━━━━━━━━━━━━━━━━━━━━━━━━━━━━━━━━━━━━━━━━━━━━━━
A7: ■ 3つの理由
A8: 理由1 | B8: 40年前の曖昧な基準 | C8: 使用従属性の判断基準が昭和60年制定で現代に不適合 | D8: ★★★★★
A9: 理由2 | B9: 弁護士による法的防御 | C9: 労働法専門弁護士が監査済み契約書を作成 | D9: ★★★★★
A10: 理由3 | B10: Win-Win構造 | C10: 企業も従業員も両方メリット→社会問題化しにくい | D10: ★★★★★
A11: ■ 市場機会
A12: 潜在市場 | B12: 日本全国の中小企業 | C12: 約380万社
A13: ターゲット | B13: 従業員10名以上 | C13: 約100万社
A14: 現実的ターゲット | B14: 従業員10-100名 | C14: 約30万社
A15: → 2年で1,000社獲得は市場の0.3%のみ（十分達成可能）
A16: ━━━━━━━━━━━━━━━━━━━━━━━━━━━━━━━━━━━━━━━━━━━━━━━━━━
A17: 第2章: 1顧客7収入モデルの全貌
A18: ━━━━━━━━━━━━━━━━━━━━━━━━━━━━━━━━━━━━━━━━━━━━━━━━━━
A19: ■ 7つの収入源（詳細）
A20: 収入 | B20: 内容 | C20: 金額 | D20: タイミング | E20: 継続性 | F20: 難易度
A21: ①初期コンサル | B21: 無料診断・提案 | C21: 0-30万円 | D21: 初回 | E21: 1回のみ | F21: 低
A22: ②成功報酬 | B22: 精算金の20-30% | C22: 500-2,000万円 | D22: 精算時 | E22: 1回のみ | F22: 中
A23: ③月額顧問料 | B23: 継続サポート | C23: 3-10万円/月 | D23: 毎月 | E23: 継続 | F23: 低
A24: ④追加サービス | B24: 研修・セミナー | C24: 10-50万円 | D24: 随時 | E24: 随時 | F24: 中
A25: ⑤紹介料 | B25: 他社紹介 | C25: 成功報酬の10% | D25: 紹介時 | E25: 随時 | F25: 低
A26: ⑥代理店フィー | B26: 代理店からの収入 | C26: 成功報酬の50% | D26: 契約時 | E26: 随時 | F26: 中
A27: ⑦アップセル | B27: 他サービス | C27: 個別見積 | D27: 随時 | E27: 随時 | F27: 高
A28: ■ 収益シミュレーション
A29: ケース | B29: 初回 | C29: 継続（年間） | D29: 合計（初年度）
A30: 小規模（10名） | B30: 500万円 | C30: 36万円 | D30: 536万円
A31: 中規模（30名） | B31: 1,200万円 | C31: 72万円 | D31: 1,272万円
A32: 大規模（100名） | B32: 3,000万円 | C32: 120万円 | D32: 3,120万円
A33: → 100社で初年度10億円超の収益可能
A34: ━━━━━━━━━━━━━━━━━━━━━━━━━━━━━━━━━━━━━━━━━━━━━━━━━━
A35: 第3章: 2年計画（なぜ2年以内なのか）
A36: ━━━━━━━━━━━━━━━━━━━━━━━━━━━━━━━━━━━━━━━━━━━━━━━━━━
A37: ■ タイムライン
A38: 時期 | B38: 状況 | C38: 対応 | D38: 目標
A39: 現在 | B39: 法律40年前、基準曖昧 | C39: バリュー社で実証 | D39: 1社成功
A40: 1-3ヶ月 | B40: 実証結果確認 | C40: 代理店10社選定 | D40: 実証完了
...

Sheet 02_法的基盤と防御戦略
A1: ⚖️ 法的基盤と防御戦略
A2: 使用従属性・4層防御・伊藤先生の叡智・リスク管理
A3: 使用従属性・弁護士戦略・4層防御・リスク管理を完全網羅
A4: 本サービスの法的基盤を支える伊藤先生の核心的ナレッジ
A5: ■ 1. 雇用契約と業務委託契約の判断基準「使用従属性」
A6: 項目 | B6: 内容 | C6: 本サービスへの影響
A7: 使用従属性とは | B7: 厚生労働省が定める雇用契約の判断基準 「使用者の指揮命令の下で労働すること」 約40年前（昭和60年）に制定された基準 | C7: 現代の働き方（リモートワーク、フレックス、 成果主義等）に対応できていない 判断が曖昧になる
A8: 判断要素の曖昧性 | B8: 使用従属性の判断要素: ①指揮監督下の労働 ②報酬の労務対償性 ③その他の要素（専属性、事業者性等） しかし「総合的に判断」という曖昧な表現 | C8: 明確な線引きが困難 個別事案ごとに判断が必要 グレーゾーンが存在する
A9: 現代の働き方との乖離 | B9: 現代の働き方: ・リモートワーク（指揮監督が見えにくい） ・フレックスタイム（時間管理が緩い） ・成果主義（労務対償性が不明確） ・副業・兼業の普及 | C9: 40年前の基準では判断が困難 業務委託契約として整理する 余地が生まれている
A10: 労働契約法の定義 | B10: 労働契約法第6条 「労働契約は、労働者が使用者に使用されて 労働し、使用者がこれに対して賃金を支払う ことについて、労働者及び使用者が合意する ことによって成立する」 | C10: 「使用されて」=使用従属性の有無 この解釈が曖昧 使用従属性の程度により 雇用契約と業務委託契約の境界が変わる
A11: ■ 2. 弁護士活用による法的防御（最重要）
A12: 戦略 | B12: 内容 | C12: 効果
A13: 弁護士による 契約書作成 | B13: 「弁護士による法的監査によって契約書を作成します」 という文言を契約書に明記 使用従属性の判断において「業務委託契約」が 適切であるという弁護士の法的見解を示す | C13: 税務署や年金事務所が異議を唱える場合、 弁護士（国家資格者）の法的判断に 異議を唱えることになる → 事実上の防御壁として機能
A14: 逃げ道の確保 | B14: 「弁護士が使用従属性を検討した結果、 業務委託契約として整理することが 法的に適切であると判断した」 という事実を契約書に残す | C14: 「弁護士の判断に基づいている」 という防御ラインを構築 企業側に悪意がないことの証明 善意の第三者として保護
A15: 国との対峙回避 | B15: 弁護士が作成した契約書に文句をつける = 国家資格者の専門的判断に異議を唱える = 国（法曹界）との対峙になる | C15: 実務上、税務署・年金事務所は 弁護士の判断を尊重せざるを得ない 介入のハードルが高くなる
A16: ■ 3. 雇用契約書の法的位置づけ
A17: 法的根拠 | B17: 詳細 | C17: 実務対応
A18: 雇用契約書は 義務ではない | B18: 労働基準法第15条: 「労働条件の明示」は義務 → 労働条件通知書の交付で足りる 雇用契約書の作成・締結は 法律で義務付けられていない | C18: あえて雇用契約書を作成しない という選択肢がある 労働条件通知書のみで 法的要件を満たす
A19: 労働条件通知書 との違い | B19: 労働条件通知書: 使用者→労働者への一方的通知 雇用契約書: 労使双方の合意を示す契約書 法的には通知書のみで問題ない | C19: 契約書という形式を避けることで 「使用従属性」の判断要素を 弱めることができる 双方合意の証拠を残さない戦略
A20: 業務委託契約書は必須 | B20: 業務委託契約では契約書が商習慣上必須 弁護士監査を経たことを明記 使用従属性が低いことを契約書で明確化: ・時間管理の自由 ・場所の自由 ・指揮命令の緩さ ・成果報酬性 | C20: こちらが主契約となる 法的整合性を確保 使用従属性の低さを 契約書で具体的に証明
A21: ■ 4. 同一労働同一賃金ガイドラインの活用
A22: 制度 | B22: 内容 | C22: 本サービスでの活用
A23: 正式名称 | B23: 「短時間・有期雇用労働者及び派遣労働者に対する 不合理な待遇の禁止等に関する指針」 （平成30年厚生労働省告示第430号） | C23: 国の政策として位置づけ 厚労省の方針に沿っている という正当性の根拠
A24: 趣旨 | B24: 雇用形態の違いによる不合理な待遇差を禁止 正規・非正規の区別なく「同一労働には同一賃金」 働き方改革関連法の一環として制定 | C24: 雇用契約と業務委託契約の 待遇差をなくす取り組み 業務内容が同じなら 契約形態を問わず公平に評価
A25: 厚労省の方針 | B25: 厚生労働省が待遇差をなくす取り組みを推進 判断要素: 「職務内容」 「職務内容・配置の変更範囲」 「その他の事情」 | C25: 本サービスはこの方針に 「乗っかっている」と主張 第三者評価により 公平な待遇を実現
A26: 営業トーク例 | B26: 「国の政策である同一労働同一賃金に基づき、 雇用形態ではなく『職務内容』で公平に評価する 制度を導入します」 | C26: 国の政策との整合性を強調 正当性をアピール 使用従属性の有無ではなく 職務内容で評価する正当性
A27: ■ 5. 使用従属性の5大判断要素と本サービスの設計
A28: 判断要素 | B28: 雇用契約（使用従属性:高） | C28: 業務委託契約（使用従属性:低） ← 本サービスの設計方針
A29: ①指揮監督性 | B29: 使用者の具体的な指揮命令の下で労働 時間・場所・方法を詳細に指定される 業務の進め方に裁量がない | C29: 自律的に業務遂行 時間・場所・方法の裁量が大きい → 成果報酬部分はこの設計 → 「成果」のみを評価
A30: ②報酬の 労務対償性 | B30: 時間給・日給・月給 労働時間に対する対価 働いた時間で報酬が決まる | C30: 成果報酬・出来高払い 成果に対する対価 → 業務委託報酬部分 → 生産性・付加価値で報酬決定
A31: ③業務の 代替性 | B31: 本人が自ら業務を行う必要あり 代替不可（労務提供義務） 欠勤時は控除 | C31: 他者への代替可能 成果物の納品が重要 → 評価制度で「成果」を測定
A32: ④専属性 | B32: 他社での就業禁止 専属的な関係 競業避止義務 | C32: 他社業務も可能 独立性が高い → 副業・兼業を認める設計
A33: ⑤事業者性 | B33: 道具・機械は会社提供 経費は会社負担 設備投資は不要 | C33: 自己の道具・機械使用 一部経費は自己負担 → 独立した事業者性を持つ
A34: 本サービスの 設計方針 | B34: 基本給部分: 使用従属性が高い部分 最低賃金ベースで設定 | C34: 業務委託報酬部分: 使用従属性が低い部分 → 第三者評価により分離 → 5要素全てで「低」を実現
A35: ■ 6. 契約書類の整備
A36: 書類 | B36: 必要性 | C36: 作成方法・記載事項
A37: 業務委託契約書 | B37: 必須 最も重要な書類 | C37: 弁護士による法的監査を経て作成 「弁護士監査済み」を明記 使用従属性が低いことを明確化: ・裁量労働の記載 ・成果報酬の明記 ・時間管理の自由 ・場所の指定なし ・代替可能性の明記
A38: 労働条件通知書 | B38: 雇用部分について必要 （雇用契約書は不要） | C38: 労働基準法第15条に基づき作成 最低限の条件を通知 基本給部分のみを記載 使用従属性が高い部分 （指揮監督下の労働）
A39: 給与明細 | B39: 雇用契約部分の支払い | C39: 基本給部分を記載 「給与」として支払い 社会保険の対象 使用従属性: 高
A40: 報酬明細 | B40: 業務委託契約部分の支払い | C40: 業務委託報酬部分を記載 「報酬」として支払い 社会保険の対象外 使用従属性: 低
...

Sheet 03_営業完全マニュアル
A1: 📞 営業完全マニュアル
A2: 9ステップ・トーク・反論処理50・ターゲット戦略
A3: 営業プロセス・9ステップ・トーク・反論処理50を完全網羅
A4: 認知から継続まで9ステージの完全営業プロセス設計
A5: ステージ | B5: タッチポイント | C5: ユーザー心理 | D5: システム対応 | E5: 提供価値 | F5: KPI | G5: 担当
A6: 認知・興味 | B6: 広告、SNS、紹介 | C6: 社会保険料が高い... 何か良い方法ないかな | D6: ランディングページ 無料診断へ誘導 | E6: 年間XX万円削減できる可能性 | F6: LP訪問数、 無料診断申込率 | G6: マーケ
A7: 無料診断 | B7: Web診断フォーム、 営業との面談 | C7: 本当に削減できる？ 違法じゃない？ | D7: 簡易シミュレーター 削減額の見える化 | E7: 具体的な削減額（数字） 法的根拠の提示 | F7: 削減額提示率100%、 商談転換率60% | G7: 営業
A8: 商談 | B8: 営業との対面/オンライン | C8: どっちのプランが良い？ 調査が来たらどうする？ | D8: 詳細シミュレーター 2プラン比較 反論処理 | E8: シンプル/フルの選択肢 調査対応の安心感 | F8: 即決率60%、 無料診断→契約率80% | G8: 営業
A9: 契約 | B9: 契約書、 初回キックオフMTG | C9: 本当に大丈夫かな... （不安） | D9: 契約管理システム 90日ロードマップ提示 | E9: 明確なスケジュール 返金保証 | F9: 契約完了率95%、 キャンセル率5%以下 | G9: 営業
A10: 導入準備 | B10: 従業員情報収集、 給与データ分析 | C10: 手間がかかりそう... | D10: データ収集フォーム 自動計算エンジン | E10: ワンストップ対応 CSの伴走 | F10: データ収集完了率100%、 30日以内完了率80% | G10: CS
A11: 実行 | B11: 労働条件通知書、 年金事務所届出 | C11: 本当にうまくいく？ | D11: 自動書類生成 届出代行 | E11: 手間ゼロ ミスゼロ | F11: 届出完了率100%、 エラー率1%以下 | G11: CS
A12: 削減開始 | B12: 給与明細、 還付金振込 | C12: ちゃんと削減された！ | D12: 削減額レポート 還付金計算 | E12: 実感できる削減額 従業員の満足度UP | F12: 削減実現率100%、 顧客満足度90%以上 | G12: CS
A13: 調査対応 | B13: 年金事務所からの通知 | C13: やっぱり来た！ どうしよう... | D13: 調査対応マニュアル Q&A自動生成 同席サポート | E13: 完全サポート 安心感 | F13: 調査突破率100%、 指摘事項0件 | G13: CS+法務
A14: 継続・拡大 | B14: 月次レポート、 追加従業員の提案 | C14: もっと従業員を増やせる？ | D14: 追加シミュレーション アップセル提案 | E14: 継続的な削減効果 LTV最大化 | F14: 継続率95%以上、 アップセル率30% | G14: CS
A15: ■ 各ステージの重要ポイント
A16: 【認知→無料診断】
A17: 【無料診断→商談】
A18: 【商談→契約】
A19: 【契約→導入】
A20: 【調査対応】
A21: 初回面談から継続サポートまで、顧客獲得の全プロセスを完全網羅
A22: ━━━━━━━━━━━━━━━━━━━━━━━━━━━━━━━━━━━━━━━━━━━━━━━━━━
A23: STEP1: 初回面談・無料診断
A24: ━━━━━━━━━━━━━━━━━━━━━━━━━━━━━━━━━━━━━━━━━━━━━━━━━━
A25: ━━━ パート1: 1-2_冒頭30秒トーク からの内容 ━━━
A26: この30秒で商談の8割が決まります。必ず暗唱してください。
A27: パート | B27: トーク内容 | C27: 目的 | D27: NG例
A28: ①挨拶 | B28: 本日はお時間ありがとうございます。 | C28: 信頼関係構築 | D28: 長い自己紹介
A29: ②ゴール確認 | B29: 今日は「社会保険料を減らす」ことより、 毎月出ている社会保険料の損失（年間XX万円）を止めて、 そのお金を従業員の給与や設備投資に回せる状態にするのがゴールで合ってますか？ | C29: 「損失を止める」に ゴールを設定 | D29: 「削減できます」 だけで終わる
A30: ③アジェンダ提示 | B30: もし合っていれば、今の社会保険料の構造を10分で整理して、 シンプルに削減 or フルサポートで守りながら削減のどちらが合うかまで、今日決めましょう。 | C30: 2プランがあることを 最初に伝える | D30: 1つのプランだけ 提示
A31: ④YES確認 | B31: （YESが出たら） ありがとうございます。 では最初に、今の社会保険料負担で経営にどんな影響が出ているか教えてください。 | C31: 当事者意識を引き出す | D31: すぐ説明を始める
A32: ■ この30秒の3つの目的
A33: 目的①
A34: 目的②
A35: 目的③
A36: ■ 応用例
A37: 業種 | B37: カスタマイズ例
A38: 製造業 | B38: 「設備投資に回せる」を強調
A39: 飲食店 | B39: 「人件費や店舗改装に回せる」を強調
A40: IT企業 | B40: 「開発費や採用費に回せる」を強調
...

Sheet 04_シミュレーター＆ツール
A1: 🧮 シミュレーター＆ツール
A2: 簡易版・詳細版・グラフ生成・計算式・使い方完全ガイド
A3: 簡易版・詳細版・グラフ生成・計算式を完全網羅
A4: 【STEP 1】基本情報を入力
A5: 変更前標準報酬月額 | C5: 円 | D5: 例: 300,000円
A6: 変更後標準報酬月額
A7: 対象期間（月数） | C7: 円 | D7: 例: 260,000円
A8: 従業員数 | C8: ヶ月 | D8: 例: 24ヶ月（2年分）
A9: 従業員数 | C9: 名 | D9: 例: 10名
A10: 【STEP 2】自動計算結果
A11: 標準報酬月額の差額 | B11: =B5-B6 -> 0 | C11: 円 | D11: 変更前 - 変更後
A12: 月額削減額（1人） | B12: =B11*0.2828 -> 0 | C12: 円 | D12: 差額 × 28.28%
A13: 年間削減額（1人） | B13: =B12*12 -> 0 | C13: 円 | D13: 月額 × 12ヶ月
A14: 【STEP 3】総還付金額
A15: 総還付金額 | B15: =B12*B7*B8 -> 0 | C15: 円 | D15: ★これが還付される総額
A16: 【STEP 4】還付金の配分（労使折半前提）
A17: 項目 | B17: 配分率 | C17: 金額 | D17: 備考
A18: 従業員への還付（50%） | B18: 50% | C18: =B16*0.5 -> 0 | D18: 1人あたり =D20/B8 | E18: =D20/B8 -> #VALUE! | F18: 円
A19: 弊社手数料（20%） | B19: 20% | C19: =B16*0.2 -> 0 | D19: 成果報酬
A20: 会社の純利益（30%） | B20: 30% | C20: =B16*0.3 -> 0 | D20: 会社に残る金額
A21: 合計 | B21: 100% | C21: =SUM(C20:C22) -> #REF!
A22: 【参考】今後の継続的コスト削減
A23: 月次削減額（全従業員） | B23: =B25*12 -> 0 | C23: 円/月 | D23: 毎月このコストが削減される
A24: 年間削減額（全従業員） | B24: =B26*12 -> #VALUE! | C24: 円/年 | D24: 年間でこのコストが削減される
A25: 【参考】社会保険料率の内訳（東京都・2024年度）
A26: 保険種類 | B26: 労使合計 | C26: 会社負担 | D26: 従業員負担 | E26: 標準報酬上限 | F26: 上限時保険料
A27: 健康保険 | B27: 9.98% | C27: 4.99% | D27: 4.99% | E27: 1,390,000円 | F27: 138,722円
A28: 厚生年金 | B28: 18.30% | C28: 9.15% | D28: 9.15% | E28: 650,000円 | F28: 118,950円
A29: 合計 | B29: 28.28% | C29: 14.14% | D29: 14.14% | E29: - | F29: -
A30: ※介護保険料（1.60%）、雇用保険、労災保険は含まれていません
A31: 【計算例】従業員10名、標準報酬月額40,000円削減、24ヶ月遡及の場合
A32: ステップ1 | B32: 標準報酬月額の差額 | C32: 40,000円
A33: ステップ2 | B33: 月額削減額（1人） | C33: 40,000 × 28.28% = 11,312円
A34: ステップ3 | B34: 総還付額 | C34: 11,312 × 24ヶ月 × 10名 = 2,714,880円
B35: 従業員還付（50%） | C35: 1,357,440円（1人あたり135,744円）
B36: 弊社手数料（20%） | C36: 542,976円
B37: 会社の純利益（30%） | C37: 814,464円
A38: ■ 計算式の説明
A39: セル | B39: 数式 | C39: 説明
A40: B11（差額） | B40: =B5-B6 -> 0 | C40: 変更前標準報酬月額 - 変更後標準報酬月額
...

Sheet 05_CS実務ガイド
A1: 💼 CS実務ガイド
A2: オンボーディング・案件管理・コミュニケーション・品質管理
A3: オンボーディング・案件管理・CS業務・コミュニケーションを完全網羅
A4: このシートでは、初回顧客を受け入れるために必要な準備を5つのフェーズで管理します。
A5: Phase | B5: フェーズ名 | C5: 期間 | D5: 目標 | E5: 主要成果物 | F5: 成功基準 | G5: 優先度 | H5: ステータス
A6: Phase 1 | B6: 基盤構築 | C6: 1-2週間 | D6: 顧客とコミュニケーションできる環境を整備 | E6: LINE公式アカウント、書類提出フォーム、契約書 | F6: 顧客からの問い合わせに即座対応できる | G6: S | H6: 未着手
A7: Phase 2 | B7: 営業基盤 | C7: 2-3週間 | D7: 見込み顧客を獲得し商談できる体制を構築 | E7: Webサイト、提案書、見積書、営業資料 | F7: 月10件の商談を実施できる | G7: S | H7: 未着手
A8: Phase 3 | B8: 業務実行基盤 | C8: 3-4週間 | D8: 契約後の業務を遂行できる体制を整備 | E8: 伊藤先生側連携、還付申請フロー、進捗管理 | F8: 初回顧客の還付申請を完了できる | G8: S | H8: 未着手
A9: Phase 4 | B9: 品質管理 | C9: 4-5週間 | D9: ミス・トラブルを防ぐ仕組みを構築 | E9: チェックリスト、エラー防止、顧客満足度調査 | F9: 顧客満足度80%以上 | G9: A | H9: 未着手
A10: Phase 5 | B10: スケール準備 | C10: 5-6週間 | D10: 10社→50社へスケールできる体制を構築 | E10: マニュアル整備、研修体制、KPI管理 | F10: 月間10社の契約を処理できる | G10: B | H10: 未着手
A11: 全体進捗
A12: Phase 1 | B12: 基盤構築 | C12: 0/12タスク完了 | H12: 0
A13: Phase 2 | B13: 営業基盤 | C13: 0/15タスク完了 | H13: 0
A14: Phase 3 | B14: 業務実行基盤 | C14: 0/10タスク完了 | H14: 0
A15: Phase 4 | B15: 品質管理 | C15: 0/8タスク完了 | H15: 0
A16: Phase 5 | B16: スケール準備 | C16: 0/10タスク完了 | H16: 0
A17: 合計 | C17: 0/55タスク完了 | H17: =SUM(H14:H18) -> #REF!
A18: ■ ステータス凡例
A19: 未着手 | B19: 準備中 | C19: 進行中 | D19: 完了
A20: ■ 進捗率の計算方法
A21: 1. H列（完了数）に完了したタスク数を手動入力
A22: 2. I列（完了率）が自動計算される（完了数 ÷ 総タスク数）
A23: 3. 全体進捗（行20）も自動集計される
B24: ※黄色セルに情報を入力してください
B25: No. | C25: 企業名 | D25: 従業員数 | E25: 年収 | F25: 還付見込額 | G25: ステータス | H25: 契約日
B26: 1 | F26: =D6*E6*5*0.2 -> #VALUE! | G26: 未着手
B27: 2 | F27: =D7*E7*5*0.2 -> #VALUE! | G27: 未着手
B28: 3 | F28: =D8*E8*5*0.2 -> #VALUE! | G28: 未着手
B29: 4 | F29: =D9*E9*5*0.2 -> #VALUE! | G29: 未着手
B30: 5 | F30: =D10*E10*5*0.2 -> #VALUE! | G30: 未着手
B31: 6 | F31: =D11*E11*5*0.2 -> 0 | G31: 未着手
B32: 7 | F32: =D12*E12*5*0.2 -> 0 | G32: 未着手
B33: 8 | F33: =D13*E13*5*0.2 -> 0 | G33: 未着手
B34: 9 | F34: =D14*E14*5*0.2 -> 0 | G34: 未着手
B35: 10 | F35: =D15*E15*5*0.2 -> 0 | G35: 未着手
B36: 11 | F36: =D16*E16*5*0.2 -> 0 | G36: 未着手
B37: 12 | F37: =D17*E17*5*0.2 -> 0 | G37: 未着手
... B55: 30 | F55: =D35*E35*5*0.2 -> 0 | G55: 未着手
A56: 顧客のライフサイクル全体で価値を最大化し、継続率・紹介率を向上させるプログラムです。
A57: フェーズ | B57: タイミング | C57: アクション | D57: 目的 | E57: ツール | F57: 担当 | G57: 成功指標
...

Sheet 06_書類・契約テンプレート
A1: 📝 書類・契約テンプレート
A2: 契約書・申請書・同意書・説明資料の完全セット
A3: 契約書類・申請書類・データ管理・チェックリストを完全網羅
A4: No | B4: 書類名 | C4: 該当STEP | D4: 提出者 | E4: 取得先 | F4: 優先度 | G4: 取得難易度 | H4: 備考
A5: 1 | B5: 協会員契約書 | C5: STEP2 | D5: クライアント | E5: 当協会 | F5: 必須 | G5: 低 | H5: 2通必要
A6: 2 | B6: 組合規定 | C6: STEP2 | D6: - | E6: 当協会 | F6: 必須 | G6: 低 | H6: 確認用
A7: 3 | B7: 印鑑証明書 | C7: STEP2 | D7: クライアント | E7: 市区町村 | F7: 条件付 | G7: 低 | H7: 場合により
A8: 4 | B8: 算定基礎届（過去5年分） | C8: STEP4 | D8: クライアント | E8: 社労士/年金事務所 | F8: 必須 | G8: 中 | H8: 試算用
A9: 5 | B9: 源泉徴収簿（過去5年分） | C9: STEP4 | D9: クライアント | E9: 自社/税理士 | F9: 必須 | G9: 中 | H9: 試算用
A10: 6 | B10: 雇用契約書（全従業員分） | C10: STEP5 | D10: クライアント | E10: 自社 | F10: 必須 | G10: 中 | H10: プラン同意後
A11: 7 | B11: 賃金台帳（過去5年分） | C11: STEP5 | D11: クライアント | E11: 自社 | F11: 必須 | G11: 中 | H11: プラン同意後
A12: 8 | B12: 就業規則 | C12: STEP5 | D12: クライアント | E12: 自社 | F12: 必須 | G12: 低 | H12: プラン同意後
A13: 9 | B13: 給与規程 | C13: STEP5 | D13: クライアント | E13: 自社 | F13: 必須 | G13: 低 | H13: プラン同意後
A14: 10 | B14: 従業員向け説明資料 | C14: STEP6 | D14: 当協会 | E14: 当協会作成 | F14: 必須 | G14: - | H14: 説明会用
A15: 11 | B15: 個別シミュレーション結果 | C15: STEP6 | D15: 当協会 | E15: 当協会作成 | F15: 必須 | G15: - | H15: 従業員ごと
... A17: 13 | B17: 業務委託契約書 | C17: STEP6 | D17: クライアント | E17: 当協会ひな形 | F17: 条件付 | G17: 低 | H17: 必要な場合
A18: 14 | B18: 過誤申立書 | C18: STEP7 | D18: 当協会 | E18: 当協会作成 | F18: 必須 | G18: -
A19: 15 | B19: 人事評価制度変更届出書 | C19: STEP7 | D19: 当協会 | E19: 当協会作成 | F19: 必須 | G19: -
A20: 16 | B20: 従業員同意書（一式） | C20: STEP7 | D20: クライアント | E20: STEP6で取得済 | F20: 必須 | G20: - | H20: 申請添付用
A21: 17 | B21: 新旧制度の比較表 | C21: STEP7 | D21: 当協会 | E21: 当協会作成 | F21: 必須 | G21: -
A22: 18 | B22: 業務実態を示す資料 | C22: STEP7 | D22: 当協会 | E22: 当協会作成 | F22: 必須 | G22: -
A23: 19 | B23: 精算決定通知書 | C23: STEP8 | D23: - | E23: 年金事務所 | F23: 自動 | G23: - | H23: 審査通過後
A24: 20 | B24: 振込明細 | C24: STEP8 | D24: - | E24: 銀行 | F24: 自動 | G24: - | H24: 入金確認用
A25: 21 | B25: 請求書（成果報酬） | C25: STEP8 | D25: 当協会 | E25: 当協会発行 | F25: 必須 | G25: -
A26: 22 | B26: 領収書 | C26: STEP8 | D26: 当協会 | E26: 当協会発行 | F26: 必須 | G26: -
A27: 23 | B27: 継続サポート契約書 | C27: STEP9 | D27: クライアント | E27: 当協会 | F27: 任意 | G27: 低 | H27: 希望者のみ
A28: リードから成約、継続まで顧客情報を一元管理します。黄色セルに入力してください。
A29: ID | B29: 会社名 | C29: 担当者名 | D29: 電話 | E29: メール | F29: LINE追加 | G29: 従業員数 | H29: 給与総額
A30: 001 | B30: サンプル株式会社 | C30: 山田太郎 | D30: 03-1234-5678 | E30: yamada@sample.co.jp | F30: 済 | G30: 50 | H30: 18,000,000
A31: 002
A32: 003
A33: 004
A34: 005
A35: ■ ステータス定義
A36: リード | B36: 初回接触～商談前
A37: 商談中 | B37: 商談実施～提案作成中
A38: 提案済 | B38: 提案書提出～意思決定待ち
A39: 成約 | B39: 契約締結完了
A40: 失注 | B40: 商談不成立
A41: 継続中 | B41: 契約履行中
...

Sheet 07_組織運営・拡大戦略
A1: 🏢 組織運営・拡大戦略
A2: 代理店戦略・KPI管理・協会運営・研修プログラム
A3: 協会運営・代理店・研修・マーケ・KPI・将来計画を完全網羅
A4: 一般社団法人としての組合設立・運営の完全ガイド
A5: ■ 組合設立のタイムライン
A6: フェーズ | B6: 期間 | C6: 内容 | D6: 必要なもの | E6: 担当
A7: Phase 1 準備 | B7: 即日〜1週間 | C7: 協会員の募集 名簿の作成 | D7: ・協会員名簿（2名以上） ・組合規約（案） | E7: 尾崎
A8: Phase 2 設立 | B8: 1日 | C8: 協会の設立 ※法人登記前でも可能 | D8: ・協会員名簿 ・組合規約（決定版） ・設立総会議事録 | E8: 全員
A9: Phase 3 運営開始 | B9: 即日〜 | C9: 組合活動の開始 協会員へのサービス提供 | D9: ・組合事務所（仮でもOK） ・連絡手段（LINE等） | E9: 全員
A10: Phase 4 法人登記 | B10: 2週間〜1ヶ月 | C10: 一般社団法人の登記 ホームページ完成後 | D10: ・定款 ・登記申請書 ・印鑑証明書等 | E10: 司法書士
A11: ■ 協会費の設定
A12: 期間 | B12: 協会費 | C12: 理由 | D12: 目的
A13: 最初の3ヶ月 | B13: 無料 | C13: 協会員を集めやすくする 事業の認知度を高める | D13: まずは協会員を増やす サービスの価値を体験してもらう
